2011-07-26 02:40:17,332 [WARNING] django.request: Not Found: /
2011-07-26 10:09:23,922 [WARNING] django.request: Not Found: /users/root/
2011-07-26 10:58:36,812 [WARNING] django.request: Not Found: /404.html
2011-07-26 11:47:49,398 [WARNING] django.request: Not Found: /css/style.css
2011-07-26 11:47:49,426 [WARNING] django.request: Not Found: /js/modernizr.js
2011-07-26 11:50:51,217 [WARNING] django.request: Not Found: /css/style.css
2011-07-26 11:50:51,229 [WARNING] django.request: Not Found: /js/modernizr.js
2011-07-26 11:59:09,345 [WARNING] django.request: Not Found: /static
2011-07-29 12:46:22,626 [WARNING] django.request: Not Found: /wiki/preview/1
2011-07-29 13:23:56,911 [WARNING] django.request: Not Found: /Link/
2011-08-03 11:39:11,718 [WARNING] django.request: Forbidden (CSRF token missing or incorrect.): /wiki/edit/1/
2011-08-03 11:49:18,819 [WARNING] django.request: Not Found: /wiki/edit/1/wiki/save
2011-08-03 11:49:32,215 [WARNING] django.request: Not Found: /wiki/edit/1/wiki/save
2011-08-03 12:17:06,548 [WARNING] django.request: Not Found: /wiki/edit
2011-08-04 10:46:29,679 [WARNING] django.request: Not Found: /login
2011-08-04 10:53:26,782 [WARNING] django.request: Not Found: /login
2011-08-04 10:54:20,196 [WARNING] django.request: Not Found: /accounts/login
2011-08-04 11:31:22,574 [WARNING] django.request: Not Found: /accounts/profile/
2011-08-04 11:31:44,452 [WARNING] django.request: Not Found: /accounts/logout
2011-08-04 11:33:33,798 [WARNING] django.request: Not Found: /accounts/profile/
2011-08-04 11:37:33,443 [WARNING] django.request: Not Found: /accounts/profile/
2011-08-04 17:58:28,724 [WARNING] django.request: Not Found: /players/players.edit_vacancy
2011-08-04 18:17:47,111 [WARNING] django.request: Not Found: /players/delete_vacancy/10/
2011-08-06 13:05:05,365 [WARNING] django.request: Not Found: /players/{% url 'messages.views.compose'            recipient=vacancy.player.user_profile.user.username             subject=[Invitation] %}
2011-08-06 13:18:07,976 [WARNING] django.request: Not Found: /players/invite_player/3/message.views.compose
2011-08-06 13:23:37,129 [WARNING] django.request: Not Found: /players/invite_player/3/message.views.compose
2011-08-06 13:27:18,912 [WARNING] django.request: Not Found: /players/invite_player/5/message.views.compose
2011-08-06 13:27:58,128 [WARNING] django.request: Not Found: /players/invite_player/5/message.views.compose
2011-08-06 13:28:04,499 [WARNING] django.request: Not Found: /players/invite_player/3/messages.views.compose
2011-08-06 13:31:15,646 [WARNING] django.request: Not Found: /players/invite_player/3/messages.views.compose
2011-08-06 13:31:18,741 [WARNING] django.request: Not Found: /players/invite_player/1/messages.views.compose
2011-08-06 13:32:40,179 [WARNING] django.request: Not Found: /players/invite_player/1/messages.views.compose
2011-08-06 13:32:59,518 [WARNING] django.request: Not Found: /players/invite_player/1/messages.views.compose
2011-08-06 13:33:51,183 [WARNING] django.request: Not Found: /players/invite_player/1/messages.views.compose
2011-08-06 13:33:54,160 [WARNING] django.request: Not Found: /players/invite_player/1/messages.views.compose
2011-08-06 13:33:59,710 [WARNING] django.request: Not Found: /players/invite_player/5/messages.views.compose
2011-08-06 13:34:46,794 [WARNING] django.request: Not Found: /players/invite_player/1/messages.views.compose
2011-08-06 13:35:14,317 [WARNING] django.request: Not Found: /players/invite_player/1/messages.views.compose
2011-08-07 10:14:21,921 [ERROR] django.request: Internal Server Error: /user_messages/compose/
Traceback (most recent call last):
  File "/home/luka/etc/saion/ht_si/env/lib/python2.7/site-packages/django/core/handlers/base.py", line 111, in get_response
    response = callback(request, *callback_args, **callback_kwargs)
  File "/home/luka/etc/saion/ht_si/env/lib/python2.7/site-packages/django/contrib/auth/decorators.py", line 23, in _wrapped_view
    return view_func(request, *args, **kwargs)
  File "/home/luka/etc/saion/ht_si/env/ht/user_messages/views.py", line 104, in compose
    context_instance=RequestContext(request))
  File "/home/luka/etc/saion/ht_si/env/lib/python2.7/site-packages/django/shortcuts/__init__.py", line 20, in render_to_response
    return HttpResponse(loader.render_to_string(*args, **kwargs), **httpresponse_kwargs)
  File "/home/luka/etc/saion/ht_si/env/lib/python2.7/site-packages/django/template/loader.py", line 188, in render_to_string
    return t.render(context_instance)
  File "/home/luka/etc/saion/ht_si/env/lib/python2.7/site-packages/django/template/base.py", line 123, in render
    return self._render(context)
  File "/home/luka/etc/saion/ht_si/env/lib/python2.7/site-packages/django/test/utils.py", line 57, in instrumented_test_render
    return self.nodelist.render(context)
  File "/home/luka/etc/saion/ht_si/env/lib/python2.7/site-packages/django/template/base.py", line 744, in render
    bits.append(self.render_node(node, context))
  File "/home/luka/etc/saion/ht_si/env/lib/python2.7/site-packages/django/template/debug.py", line 73, in render_node
    result = node.render(context)
  File "/home/luka/etc/saion/ht_si/env/lib/python2.7/site-packages/django/template/loader_tags.py", line 105, in render
    compiled_parent = self.get_parent(context)
  File "/home/luka/etc/saion/ht_si/env/lib/python2.7/site-packages/django/template/loader_tags.py", line 102, in get_parent
    return get_template(parent)
  File "/home/luka/etc/saion/ht_si/env/lib/python2.7/site-packages/django/template/loader.py", line 157, in get_template
    template, origin = find_template(template_name)
  File "/home/luka/etc/saion/ht_si/env/lib/python2.7/site-packages/django/template/loader.py", line 138, in find_template
    raise TemplateDoesNotExist(name)
TemplateSyntaxError: Caught TemplateDoesNotExist while rendering: messages/base.html
2011-08-07 10:14:21,944 [ERROR] django.request: Internal Server Error: /user_messages/inbox/
Traceback (most recent call last):
  File "/home/luka/etc/saion/ht_si/env/lib/python2.7/site-packages/django/core/handlers/base.py", line 111, in get_response
    response = callback(request, *callback_args, **callback_kwargs)
  File "/home/luka/etc/saion/ht_si/env/lib/python2.7/site-packages/django/contrib/auth/decorators.py", line 23, in _wrapped_view
    return view_func(request, *args, **kwargs)
  File "/home/luka/etc/saion/ht_si/env/ht/user_messages/views.py", line 34, in inbox
    }, context_instance=RequestContext(request))
  File "/home/luka/etc/saion/ht_si/env/lib/python2.7/site-packages/django/shortcuts/__init__.py", line 20, in render_to_response
    return HttpResponse(loader.render_to_string(*args, **kwargs), **httpresponse_kwargs)
  File "/home/luka/etc/saion/ht_si/env/lib/python2.7/site-packages/django/template/loader.py", line 188, in render_to_string
    return t.render(context_instance)
  File "/home/luka/etc/saion/ht_si/env/lib/python2.7/site-packages/django/template/base.py", line 123, in render
    return self._render(context)
  File "/home/luka/etc/saion/ht_si/env/lib/python2.7/site-packages/django/test/utils.py", line 57, in instrumented_test_render
    return self.nodelist.render(context)
  File "/home/luka/etc/saion/ht_si/env/lib/python2.7/site-packages/django/template/base.py", line 744, in render
    bits.append(self.render_node(node, context))
  File "/home/luka/etc/saion/ht_si/env/lib/python2.7/site-packages/django/template/debug.py", line 73, in render_node
    result = node.render(context)
  File "/home/luka/etc/saion/ht_si/env/lib/python2.7/site-packages/django/template/loader_tags.py", line 105, in render
    compiled_parent = self.get_parent(context)
  File "/home/luka/etc/saion/ht_si/env/lib/python2.7/site-packages/django/template/loader_tags.py", line 102, in get_parent
    return get_template(parent)
  File "/home/luka/etc/saion/ht_si/env/lib/python2.7/site-packages/django/template/loader.py", line 157, in get_template
    template, origin = find_template(template_name)
  File "/home/luka/etc/saion/ht_si/env/lib/python2.7/site-packages/django/template/loader.py", line 138, in find_template
    raise TemplateDoesNotExist(name)
TemplateSyntaxError: Caught TemplateDoesNotExist while rendering: messages/base.html
2011-08-07 10:14:21,961 [ERROR] django.request: Internal Server Error: /user_messages/outbox/
Traceback (most recent call last):
  File "/home/luka/etc/saion/ht_si/env/lib/python2.7/site-packages/django/core/handlers/base.py", line 111, in get_response
    response = callback(request, *callback_args, **callback_kwargs)
  File "/home/luka/etc/saion/ht_si/env/lib/python2.7/site-packages/django/contrib/auth/decorators.py", line 23, in _wrapped_view
    return view_func(request, *args, **kwargs)
  File "/home/luka/etc/saion/ht_si/env/ht/user_messages/views.py", line 47, in outbox
    }, context_instance=RequestContext(request))
  File "/home/luka/etc/saion/ht_si/env/lib/python2.7/site-packages/django/shortcuts/__init__.py", line 20, in render_to_response
    return HttpResponse(loader.render_to_string(*args, **kwargs), **httpresponse_kwargs)
  File "/home/luka/etc/saion/ht_si/env/lib/python2.7/site-packages/django/template/loader.py", line 188, in render_to_string
    return t.render(context_instance)
  File "/home/luka/etc/saion/ht_si/env/lib/python2.7/site-packages/django/template/base.py", line 123, in render
    return self._render(context)
  File "/home/luka/etc/saion/ht_si/env/lib/python2.7/site-packages/django/test/utils.py", line 57, in instrumented_test_render
    return self.nodelist.render(context)
  File "/home/luka/etc/saion/ht_si/env/lib/python2.7/site-packages/django/template/base.py", line 744, in render
    bits.append(self.render_node(node, context))
  File "/home/luka/etc/saion/ht_si/env/lib/python2.7/site-packages/django/template/debug.py", line 73, in render_node
    result = node.render(context)
  File "/home/luka/etc/saion/ht_si/env/lib/python2.7/site-packages/django/template/loader_tags.py", line 105, in render
    compiled_parent = self.get_parent(context)
  File "/home/luka/etc/saion/ht_si/env/lib/python2.7/site-packages/django/template/loader_tags.py", line 102, in get_parent
    return get_template(parent)
  File "/home/luka/etc/saion/ht_si/env/lib/python2.7/site-packages/django/template/loader.py", line 157, in get_template
    template, origin = find_template(template_name)
  File "/home/luka/etc/saion/ht_si/env/lib/python2.7/site-packages/django/template/loader.py", line 138, in find_template
    raise TemplateDoesNotExist(name)
TemplateSyntaxError: Caught TemplateDoesNotExist while rendering: messages/base.html
2011-08-07 10:14:21,986 [ERROR] django.request: Internal Server Error: /user_messages/inbox/
Traceback (most recent call last):
  File "/home/luka/etc/saion/ht_si/env/lib/python2.7/site-packages/django/core/handlers/base.py", line 111, in get_response
    response = callback(request, *callback_args, **callback_kwargs)
  File "/home/luka/etc/saion/ht_si/env/lib/python2.7/site-packages/django/contrib/auth/decorators.py", line 23, in _wrapped_view
    return view_func(request, *args, **kwargs)
  File "/home/luka/etc/saion/ht_si/env/ht/user_messages/views.py", line 34, in inbox
    }, context_instance=RequestContext(request))
  File "/home/luka/etc/saion/ht_si/env/lib/python2.7/site-packages/django/shortcuts/__init__.py", line 20, in render_to_response
    return HttpResponse(loader.render_to_string(*args, **kwargs), **httpresponse_kwargs)
  File "/home/luka/etc/saion/ht_si/env/lib/python2.7/site-packages/django/template/loader.py", line 188, in render_to_string
    return t.render(context_instance)
  File "/home/luka/etc/saion/ht_si/env/lib/python2.7/site-packages/django/template/base.py", line 123, in render
    return self._render(context)
  File "/home/luka/etc/saion/ht_si/env/lib/python2.7/site-packages/django/test/utils.py", line 57, in instrumented_test_render
    return self.nodelist.render(context)
  File "/home/luka/etc/saion/ht_si/env/lib/python2.7/site-packages/django/template/base.py", line 744, in render
    bits.append(self.render_node(node, context))
  File "/home/luka/etc/saion/ht_si/env/lib/python2.7/site-packages/django/template/debug.py", line 73, in render_node
    result = node.render(context)
  File "/home/luka/etc/saion/ht_si/env/lib/python2.7/site-packages/django/template/loader_tags.py", line 105, in render
    compiled_parent = self.get_parent(context)
  File "/home/luka/etc/saion/ht_si/env/lib/python2.7/site-packages/django/template/loader_tags.py", line 102, in get_parent
    return get_template(parent)
  File "/home/luka/etc/saion/ht_si/env/lib/python2.7/site-packages/django/template/loader.py", line 157, in get_template
    template, origin = find_template(template_name)
  File "/home/luka/etc/saion/ht_si/env/lib/python2.7/site-packages/django/template/loader.py", line 138, in find_template
    raise TemplateDoesNotExist(name)
TemplateSyntaxError: Caught TemplateDoesNotExist while rendering: messages/base.html
2011-08-07 10:14:22,004 [ERROR] django.request: Internal Server Error: /user_messages/trash/
Traceback (most recent call last):
  File "/home/luka/etc/saion/ht_si/env/lib/python2.7/site-packages/django/core/handlers/base.py", line 111, in get_response
    response = callback(request, *callback_args, **callback_kwargs)
  File "/home/luka/etc/saion/ht_si/env/lib/python2.7/site-packages/django/contrib/auth/decorators.py", line 23, in _wrapped_view
    return view_func(request, *args, **kwargs)
  File "/home/luka/etc/saion/ht_si/env/ht/user_messages/views.py", line 64, in trash
    }, context_instance=RequestContext(request))
  File "/home/luka/etc/saion/ht_si/env/lib/python2.7/site-packages/django/shortcuts/__init__.py", line 20, in render_to_response
    return HttpResponse(loader.render_to_string(*args, **kwargs), **httpresponse_kwargs)
  File "/home/luka/etc/saion/ht_si/env/lib/python2.7/site-packages/django/template/loader.py", line 188, in render_to_string
    return t.render(context_instance)
  File "/home/luka/etc/saion/ht_si/env/lib/python2.7/site-packages/django/template/base.py", line 123, in render
    return self._render(context)
  File "/home/luka/etc/saion/ht_si/env/lib/python2.7/site-packages/django/test/utils.py", line 57, in instrumented_test_render
    return self.nodelist.render(context)
  File "/home/luka/etc/saion/ht_si/env/lib/python2.7/site-packages/django/template/base.py", line 744, in render
    bits.append(self.render_node(node, context))
  File "/home/luka/etc/saion/ht_si/env/lib/python2.7/site-packages/django/template/debug.py", line 73, in render_node
    result = node.render(context)
  File "/home/luka/etc/saion/ht_si/env/lib/python2.7/site-packages/django/template/loader_tags.py", line 105, in render
    compiled_parent = self.get_parent(context)
  File "/home/luka/etc/saion/ht_si/env/lib/python2.7/site-packages/django/template/loader_tags.py", line 102, in get_parent
    return get_template(parent)
  File "/home/luka/etc/saion/ht_si/env/lib/python2.7/site-packages/django/template/loader.py", line 157, in get_template
    template, origin = find_template(template_name)
  File "/home/luka/etc/saion/ht_si/env/lib/python2.7/site-packages/django/template/loader.py", line 138, in find_template
    raise TemplateDoesNotExist(name)
TemplateSyntaxError: Caught TemplateDoesNotExist while rendering: messages/base.html
2011-08-07 10:16:26,290 [ERROR] django.request: Internal Server Error: /user_messages/compose/
Traceback (most recent call last):
  File "/home/luka/etc/saion/ht_si/env/lib/python2.7/site-packages/django/core/handlers/base.py", line 111, in get_response
    response = callback(request, *callback_args, **callback_kwargs)
  File "/home/luka/etc/saion/ht_si/env/lib/python2.7/site-packages/django/contrib/auth/decorators.py", line 23, in _wrapped_view
    return view_func(request, *args, **kwargs)
  File "/home/luka/etc/saion/ht_si/env/ht/user_messages/views.py", line 91, in compose
    success_url = reverse('messages_inbox')
  File "/home/luka/etc/saion/ht_si/env/lib/python2.7/site-packages/django/core/urlresolvers.py", line 391, in reverse
    *args, **kwargs)))
  File "/home/luka/etc/saion/ht_si/env/lib/python2.7/site-packages/django/core/urlresolvers.py", line 337, in reverse
    "arguments '%s' not found." % (lookup_view_s, args, kwargs))
NoReverseMatch: Reverse for 'messages_inbox' with arguments '()' and keyword arguments '{}' not found.
2011-08-07 10:16:26,363 [ERROR] django.request: Internal Server Error: /user_messages/inbox/
Traceback (most recent call last):
  File "/home/luka/etc/saion/ht_si/env/lib/python2.7/site-packages/django/core/handlers/base.py", line 111, in get_response
    response = callback(request, *callback_args, **callback_kwargs)
  File "/home/luka/etc/saion/ht_si/env/lib/python2.7/site-packages/django/contrib/auth/decorators.py", line 23, in _wrapped_view
    return view_func(request, *args, **kwargs)
  File "/home/luka/etc/saion/ht_si/env/ht/user_messages/views.py", line 34, in inbox
    }, context_instance=RequestContext(request))
  File "/home/luka/etc/saion/ht_si/env/lib/python2.7/site-packages/django/shortcuts/__init__.py", line 20, in render_to_response
    return HttpResponse(loader.render_to_string(*args, **kwargs), **httpresponse_kwargs)
  File "/home/luka/etc/saion/ht_si/env/lib/python2.7/site-packages/django/template/loader.py", line 188, in render_to_string
    return t.render(context_instance)
  File "/home/luka/etc/saion/ht_si/env/lib/python2.7/site-packages/django/template/base.py", line 123, in render
    return self._render(context)
  File "/home/luka/etc/saion/ht_si/env/lib/python2.7/site-packages/django/test/utils.py", line 57, in instrumented_test_render
    return self.nodelist.render(context)
  File "/home/luka/etc/saion/ht_si/env/lib/python2.7/site-packages/django/template/base.py", line 744, in render
    bits.append(self.render_node(node, context))
  File "/home/luka/etc/saion/ht_si/env/lib/python2.7/site-packages/django/template/debug.py", line 73, in render_node
    result = node.render(context)
  File "/home/luka/etc/saion/ht_si/env/lib/python2.7/site-packages/django/template/loader_tags.py", line 127, in render
    return compiled_parent._render(context)
  File "/home/luka/etc/saion/ht_si/env/lib/python2.7/site-packages/django/test/utils.py", line 57, in instrumented_test_render
    return self.nodelist.render(context)
  File "/home/luka/etc/saion/ht_si/env/lib/python2.7/site-packages/django/template/base.py", line 744, in render
    bits.append(self.render_node(node, context))
  File "/home/luka/etc/saion/ht_si/env/lib/python2.7/site-packages/django/template/debug.py", line 73, in render_node
    result = node.render(context)
  File "/home/luka/etc/saion/ht_si/env/lib/python2.7/site-packages/django/template/loader_tags.py", line 127, in render
    return compiled_parent._render(context)
  File "/home/luka/etc/saion/ht_si/env/lib/python2.7/site-packages/django/test/utils.py", line 57, in instrumented_test_render
    return self.nodelist.render(context)
  File "/home/luka/etc/saion/ht_si/env/lib/python2.7/site-packages/django/template/base.py", line 744, in render
    bits.append(self.render_node(node, context))
  File "/home/luka/etc/saion/ht_si/env/lib/python2.7/site-packages/django/template/debug.py", line 73, in render_node
    result = node.render(context)
  File "/home/luka/etc/saion/ht_si/env/lib/python2.7/site-packages/django/template/defaulttags.py", line 311, in render
    return self.nodelist_true.render(context)
  File "/home/luka/etc/saion/ht_si/env/lib/python2.7/site-packages/django/template/base.py", line 744, in render
    bits.append(self.render_node(node, context))
  File "/home/luka/etc/saion/ht_si/env/lib/python2.7/site-packages/django/template/debug.py", line 73, in render_node
    result = node.render(context)
  File "/home/luka/etc/saion/ht_si/env/lib/python2.7/site-packages/django/template/loader_tags.py", line 64, in render
    result = block.nodelist.render(context)
  File "/home/luka/etc/saion/ht_si/env/lib/python2.7/site-packages/django/template/base.py", line 744, in render
    bits.append(self.render_node(node, context))
  File "/home/luka/etc/saion/ht_si/env/lib/python2.7/site-packages/django/template/debug.py", line 73, in render_node
    result = node.render(context)
  File "/home/luka/etc/saion/ht_si/env/lib/python2.7/site-packages/django/template/loader_tags.py", line 64, in render
    result = block.nodelist.render(context)
  File "/home/luka/etc/saion/ht_si/env/lib/python2.7/site-packages/django/template/base.py", line 744, in render
    bits.append(self.render_node(node, context))
  File "/home/luka/etc/saion/ht_si/env/lib/python2.7/site-packages/django/template/debug.py", line 73, in render_node
    result = node.render(context)
  File "/home/luka/etc/saion/ht_si/env/lib/python2.7/site-packages/django/template/defaulttags.py", line 311, in render
    return self.nodelist_true.render(context)
  File "/home/luka/etc/saion/ht_si/env/lib/python2.7/site-packages/django/template/base.py", line 744, in render
    bits.append(self.render_node(node, context))
  File "/home/luka/etc/saion/ht_si/env/lib/python2.7/site-packages/django/template/debug.py", line 73, in render_node
    result = node.render(context)
  File "/home/luka/etc/saion/ht_si/env/lib/python2.7/site-packages/django/template/defaulttags.py", line 227, in render
    nodelist.append(node.render(context))
  File "/home/luka/etc/saion/ht_si/env/lib/python2.7/site-packages/django/template/defaulttags.py", line 450, in render
    raise e
TemplateSyntaxError: Caught NoReverseMatch while rendering: Reverse for 'messages_delete' with arguments '(1,)' and keyword arguments '{}' not found.
2011-08-07 10:18:33,874 [ERROR] django.request: Internal Server Error: /user_messages/compose/
Traceback (most recent call last):
  File "/home/luka/etc/saion/ht_si/env/lib/python2.7/site-packages/django/core/handlers/base.py", line 111, in get_response
    response = callback(request, *callback_args, **callback_kwargs)
  File "/home/luka/etc/saion/ht_si/env/lib/python2.7/site-packages/django/contrib/auth/decorators.py", line 23, in _wrapped_view
    return view_func(request, *args, **kwargs)
  File "/home/luka/etc/saion/ht_si/env/ht/user_messages/views.py", line 91, in compose
    success_url = reverse('messages_inbox')
  File "/home/luka/etc/saion/ht_si/env/lib/python2.7/site-packages/django/core/urlresolvers.py", line 391, in reverse
    *args, **kwargs)))
  File "/home/luka/etc/saion/ht_si/env/lib/python2.7/site-packages/django/core/urlresolvers.py", line 337, in reverse
    "arguments '%s' not found." % (lookup_view_s, args, kwargs))
NoReverseMatch: Reverse for 'messages_inbox' with arguments '()' and keyword arguments '{}' not found.
2011-08-07 10:19:17,948 [ERROR] django.request: Internal Server Error: /user_messages/compose/
Traceback (most recent call last):
  File "/home/luka/etc/saion/ht_si/env/lib/python2.7/site-packages/django/core/handlers/base.py", line 111, in get_response
    response = callback(request, *callback_args, **callback_kwargs)
  File "/home/luka/etc/saion/ht_si/env/lib/python2.7/site-packages/django/contrib/auth/decorators.py", line 23, in _wrapped_view
    return view_func(request, *args, **kwargs)
  File "/home/luka/etc/saion/ht_si/env/ht/user_messages/views.py", line 91, in compose
    success_url = reverse('messages_inbox')
  File "/home/luka/etc/saion/ht_si/env/lib/python2.7/site-packages/django/core/urlresolvers.py", line 391, in reverse
    *args, **kwargs)))
  File "/home/luka/etc/saion/ht_si/env/lib/python2.7/site-packages/django/core/urlresolvers.py", line 337, in reverse
    "arguments '%s' not found." % (lookup_view_s, args, kwargs))
NoReverseMatch: Reverse for 'messages_inbox' with arguments '()' and keyword arguments '{}' not found.
2011-08-07 10:22:31,919 [ERROR] django.request: Internal Server Error: /user_messages/compose/
Traceback (most recent call last):
  File "/home/luka/etc/saion/ht_si/env/lib/python2.7/site-packages/django/core/handlers/base.py", line 111, in get_response
    response = callback(request, *callback_args, **callback_kwargs)
  File "/home/luka/etc/saion/ht_si/env/lib/python2.7/site-packages/django/contrib/auth/decorators.py", line 23, in _wrapped_view
    return view_func(request, *args, **kwargs)
  File "/home/luka/etc/saion/ht_si/env/ht/user_messages/views.py", line 91, in compose
    success_url = reverse('messages_inbox')
  File "/home/luka/etc/saion/ht_si/env/lib/python2.7/site-packages/django/core/urlresolvers.py", line 391, in reverse
    *args, **kwargs)))
  File "/home/luka/etc/saion/ht_si/env/lib/python2.7/site-packages/django/core/urlresolvers.py", line 337, in reverse
    "arguments '%s' not found." % (lookup_view_s, args, kwargs))
NoReverseMatch: Reverse for 'messages_inbox' with arguments '()' and keyword arguments '{}' not found.
2011-08-08 11:32:51,912 [WARNING] django.request: Not Found: /django_messages/inbox/
2011-08-11 11:17:50,871 [WARNING] django.request: Not Found: /upload/images/test_1.jpg
2011-08-11 11:17:51,046 [WARNING] django.request: Not Found: /upload/images/test_1.jpg
2011-08-11 11:21:47,832 [WARNING] django.request: Not Found: /upload/images/test_1.jpg
2011-08-11 11:21:48,033 [WARNING] django.request: Not Found: /upload/images/test_1.jpg
2011-08-11 11:23:08,150 [WARNING] django.request: Not Found: /upload/images/test_1.jpg
2011-08-11 11:23:08,326 [WARNING] django.request: Not Found: /upload/images/test_1.jpg
2011-08-11 11:23:10,780 [WARNING] django.request: Not Found: /upload/images/test_1.jpg
2011-08-11 11:23:10,979 [WARNING] django.request: Not Found: /upload/images/test_1.jpg
2011-08-11 11:24:03,166 [WARNING] django.request: Not Found: /upload/images/test_1.jpg
2011-08-11 11:24:03,340 [WARNING] django.request: Not Found: /upload/images/test_1.jpg
2011-08-11 11:31:52,773 [WARNING] django.request: Not Found: /upload/images/test.jpg
2011-08-11 11:32:17,002 [WARNING] django.request: Not Found: /upload/images/test_1.jpg
2011-08-11 11:56:25,067 [WARNING] django.request: Not Found: /ranking/comment_match/1/
2011-08-11 14:13:18,953 [WARNING] django.request: Not Found: /upload/comment_photos/test.jpg
2011-08-11 14:13:19,113 [WARNING] django.request: Not Found: /upload/comment_photos/test.jpg
2011-08-11 18:59:21,638 [WARNING] django.request: Not Found: /upload/comment_photos/test.jpg
2011-08-11 18:59:21,671 [WARNING] django.request: Not Found: /upload/comment_photos/test.jpg
2011-08-13 13:41:29,826 [WARNING] django.request: Not Found: /favicon.ico
2011-08-13 13:41:29,877 [WARNING] django.request: Not Found: /favicon.ico
2011-08-15 17:37:17,629 [WARNING] django.request: Not Found: /img/find_partner.png
2011-08-15 17:38:28,484 [WARNING] django.request: Not Found: /img/find_partner.png
2011-08-15 17:38:28,621 [WARNING] django.request: Not Found: /img/find_partner.png
2011-08-15 17:50:35,949 [WARNING] django.request: Not Found: /favicon.ico
2011-08-15 17:50:35,999 [WARNING] django.request: Not Found: /favicon.ico
2011-08-16 15:01:03,635 [WARNING] django.request: Not Found: /favicon.ico
2011-08-16 16:27:44,111 [WARNING] django.request: Not Found: /favicon.ico
2011-08-16 16:27:59,177 [WARNING] django.request: Not Found: /favicon.ico
2011-08-16 16:28:21,805 [WARNING] django.request: Not Found: /favicon.ico
2011-08-16 16:28:22,450 [WARNING] django.request: Not Found: /favicon.ico
2011-08-16 16:29:34,048 [WARNING] django.request: Not Found: /favicon.ico
2011-08-16 16:29:37,110 [WARNING] django.request: Not Found: /favicon.ico
2011-08-17 14:49:38,520 [WARNING] django.request: Not Found: /favicon.ico
2011-08-17 14:49:48,519 [WARNING] django.request: Not Found: /favicon.ico
2011-08-17 14:49:52,846 [WARNING] django.request: Not Found: /favicon.ico
2011-08-17 14:49:56,959 [WARNING] django.request: Not Found: /favicon.ico
2011-08-18 12:57:07,674 [WARNING] django.request: Not Found: /favicon.ico
2011-08-18 12:57:11,176 [WARNING] django.request: Not Found: /favicon.ico
2011-08-19 12:51:15,836 [WARNING] django.request: Not Found: /favicon.ico
2011-08-19 12:51:20,490 [WARNING] django.request: Not Found: /favicon.ico
2011-08-19 12:51:23,618 [WARNING] django.request: Not Found: /favicon.ico
2011-08-19 12:53:27,739 [WARNING] django.request: Not Found: /favicon.ico
2011-08-19 12:53:32,441 [WARNING] django.request: Not Found: /favicon.ico
2011-08-20 10:38:27,654 [WARNING] django.request: Not Found: /favicon.ico
2011-08-20 10:38:27,708 [WARNING] django.request: Not Found: /favicon.ico
2011-08-20 13:35:31,655 [WARNING] django.request: Not Found: /favicon.ico
2011-08-20 13:35:36,038 [WARNING] django.request: Not Found: /favicon.ico
2011-08-20 13:35:42,279 [WARNING] django.request: Not Found: /favicon.ico
2011-08-20 13:35:47,013 [WARNING] django.request: Not Found: /favicon.ico
2011-08-20 13:35:52,745 [WARNING] django.request: Not Found: /favicon.ico
2011-08-20 13:36:14,047 [WARNING] django.request: Not Found: /favicon.ico
2011-08-20 13:36:27,820 [WARNING] django.request: Not Found: /favicon.ico
2011-08-20 15:05:43,976 [WARNING] django.request: Not Found: /favicon.ico
2011-08-21 16:08:24,882 [WARNING] django.request: Not Found: /favicon.ico
2011-08-21 16:08:24,981 [WARNING] django.request: Not Found: /favicon.ico
2011-08-22 20:50:26,973 [WARNING] django.request: Not Found: /favicon.ico
2011-08-22 20:50:29,865 [WARNING] django.request: Not Found: /favicon.ico
2011-08-22 20:50:33,847 [WARNING] django.request: Not Found: /favicon.ico
2011-08-22 20:50:37,889 [WARNING] django.request: Not Found: /favicon.ico
2011-08-22 22:12:05,338 [WARNING] django.request: Not Found: /favicon.ico
2011-09-14 13:06:46,661 [WARNING] django.request: Not Found: /favicon.ico
2011-09-14 13:06:46,699 [WARNING] django.request: Not Found: /favicon.ico
2011-09-18 11:16:17,721 [WARNING] django.request: Not Found: /favicon.ico
2011-09-18 11:16:17,740 [WARNING] django.request: Not Found: /favicon.ico
2011-09-26 14:50:19,494 [WARNING] django.request: Not Found: /accounts/img/clay.png
2011-09-26 14:50:19,777 [WARNING] django.request: Not Found: /accounts/img/clay.png
2011-09-26 14:51:31,300 [WARNING] django.request: Not Found: /accounts/img/clay.png
2011-09-26 14:51:31,391 [WARNING] django.request: Not Found: /accounts/img/clay.png
2011-09-28 13:15:01,930 [WARNING] django.request: Not Found: /clubs/edit_court_setup/
2011-09-28 21:22:07,045 [WARNING] django.request: Not Found: /favicon.ico
2011-10-01 09:50:24,683 [WARNING] django.request: Not Found: /favicon.ico
2011-10-01 09:50:24,691 [WARNING] django.request: Not Found: /favicon.ico
2011-10-01 10:00:44,838 [WARNING] django.request: Not Found: /favicon.ico
2011-10-02 16:41:56,775 [WARNING] django.request: Not Found: /favicon.ico
2011-10-02 17:36:32,455 [WARNING] django.request: Not Found: /favicon.ico
2011-10-02 17:45:21,234 [WARNING] django.request: Not Found: /favicon.ico
2011-10-02 17:45:33,610 [WARNING] django.request: Not Found: /favicon.ico
2011-10-02 17:46:33,702 [WARNING] django.request: Not Found: /favicon.ico
2011-10-02 17:46:51,448 [WARNING] django.request: Not Found: /favicon.ico
2011-10-02 17:49:02,273 [WARNING] django.request: Not Found: /favicon.ico
2011-10-02 17:50:14,464 [WARNING] django.request: Not Found: /favicon.ico
2011-10-02 17:50:21,263 [WARNING] django.request: Not Found: /favicon.ico
2011-10-02 17:50:33,745 [WARNING] django.request: Not Found: /favicon.ico
2011-10-02 17:50:49,216 [WARNING] django.request: Not Found: /favicon.ico
2011-10-02 17:51:15,813 [WARNING] django.request: Not Found: /favicon.ico
2011-10-03 11:29:20,560 [WARNING] django.request: Forbidden (CSRF token missing or incorrect.): /clubs/save_court_vacancy/1/
2011-10-04 13:34:31,033 [WARNING] django.request: Not Found: /clubs/edit_court_properties/5/
2011-10-04 13:34:36,764 [WARNING] django.request: Not Found: /clubs/edit_court_properties/5/
2011-10-09 19:19:38,370 [WARNING] django.request: Not Found: /favicon.ico
2011-10-09 19:19:38,388 [WARNING] django.request: Not Found: /favicon.ico
2011-10-09 21:11:48,780 [WARNING] django.request: Not Found: /favicon.ico
2011-10-12 09:33:16,062 [WARNING] django.request: Not Found: /reservations/make_reservation
2011-10-12 16:35:31,453 [WARNING] django.request: Not Found: /favicon.ico
2011-10-12 16:35:41,331 [WARNING] django.request: Not Found: /favicon.ico
2011-10-12 16:35:49,580 [WARNING] django.request: Not Found: /favicon.ico
2011-10-12 16:35:57,328 [WARNING] django.request: Not Found: /favicon.ico
2011-10-12 16:37:00,401 [WARNING] django.request: Not Found: /favicon.ico
2011-10-12 16:37:11,942 [WARNING] django.request: Not Found: /favicon.ico
2011-10-12 16:37:37,662 [WARNING] django.request: Not Found: /favicon.ico
2011-10-12 16:37:39,310 [WARNING] django.request: Not Found: /favicon.ico
2011-10-12 16:37:40,589 [WARNING] django.request: Not Found: /favicon.ico
2011-10-12 16:37:44,320 [WARNING] django.request: Not Found: /favicon.ico
2011-10-12 16:38:00,509 [WARNING] django.request: Not Found: /favicon.ico
2011-10-12 16:38:02,753 [WARNING] django.request: Not Found: /favicon.ico
2011-10-12 16:38:08,882 [WARNING] django.request: Not Found: /favicon.ico
2011-10-12 16:39:20,279 [WARNING] django.request: Not Found: /favicon.ico
2011-10-12 17:02:27,056 [WARNING] django.request: Not Found: /favicon.ico
2011-10-12 17:02:28,891 [WARNING] django.request: Not Found: /favicon.ico
2011-10-12 17:55:16,724 [WARNING] django.request: Not Found: /favicon.ico
2011-10-12 17:55:20,100 [WARNING] django.request: Not Found: /favicon.ico
2011-10-12 17:55:28,394 [WARNING] django.request: Not Found: /favicon.ico
2011-10-12 17:55:40,601 [WARNING] django.request: Not Found: /favicon.ico
2011-10-12 17:55:41,905 [WARNING] django.request: Not Found: /favicon.ico
2011-10-12 17:55:42,587 [WARNING] django.request: Not Found: /favicon.ico
2011-10-12 17:57:59,610 [WARNING] django.request: Not Found: /favicon.ico
2011-10-12 17:58:00,351 [WARNING] django.request: Not Found: /favicon.ico
2011-10-12 17:58:02,387 [WARNING] django.request: Not Found: /favicon.ico
2011-10-12 17:58:05,360 [WARNING] django.request: Not Found: /favicon.ico
2011-10-12 17:58:52,599 [WARNING] django.request: Not Found: /favicon.ico
2011-10-12 18:00:37,455 [WARNING] django.request: Not Found: /favicon.ico
2011-10-12 18:00:38,759 [WARNING] django.request: Not Found: /favicon.ico
2011-10-12 18:00:48,545 [WARNING] django.request: Not Found: /favicon.ico
2011-10-12 18:01:06,477 [WARNING] django.request: Not Found: /favicon.ico
2011-10-12 18:05:33,070 [WARNING] django.request: Not Found: /favicon.ico
2011-10-12 18:05:37,351 [WARNING] django.request: Not Found: /favicon.ico
2011-10-12 18:05:44,574 [WARNING] django.request: Not Found: /favicon.ico
2011-10-12 18:12:41,563 [WARNING] django.request: Not Found: /favicon.ico
2011-10-12 18:12:49,572 [WARNING] django.request: Not Found: /favicon.ico
2011-10-12 18:12:52,159 [WARNING] django.request: Not Found: /favicon.ico
2011-10-12 18:12:53,051 [WARNING] django.request: Not Found: /favicon.ico
2011-10-12 18:12:54,400 [WARNING] django.request: Not Found: /favicon.ico
2011-10-12 18:13:01,260 [WARNING] django.request: Not Found: /favicon.ico
2011-10-12 18:13:02,078 [WARNING] django.request: Not Found: /favicon.ico
2011-10-12 18:13:03,544 [WARNING] django.request: Not Found: /favicon.ico
2011-10-12 18:13:11,859 [WARNING] django.request: Not Found: /favicon.ico
2011-10-12 18:13:13,124 [WARNING] django.request: Not Found: /favicon.ico
2011-10-13 11:38:00,683 [WARNING] django.request: Not Found: /reservations/price_190
2011-10-13 11:41:43,537 [WARNING] django.request: Not Found: /reservations/price_190
2011-10-14 11:39:31,297 [WARNING] django.request: Not Found: /favicon.ico
2011-10-14 11:39:31,378 [WARNING] django.request: Not Found: /favicon.ico
2011-10-14 16:17:53,490 [WARNING] django.request: Not Found: /favicon.ico
2011-10-14 16:17:53,539 [WARNING] django.request: Not Found: /favicon.ico
2011-10-14 18:48:51,355 [WARNING] django.request: Not Found: /reservations/price_198
2011-10-16 15:15:57,544 [WARNING] django.request: Not Found: /reservations/create/734426/232/
2011-10-16 15:16:03,283 [WARNING] django.request: Not Found: /reservations/create/734426/232/
2011-10-17 17:24:13,883 [WARNING] django.request: Not Found: /reservations/title="Rubber"/
2011-10-17 17:24:13,986 [WARNING] django.request: Not Found: /reservations/title="Rubber"/
2011-10-17 17:24:42,252 [WARNING] django.request: Not Found: /reservations/title="Carpet"/
2011-10-17 17:24:42,342 [WARNING] django.request: Not Found: /reservations/title="Carpet"/
2011-10-17 21:58:33,890 [WARNING] django.request: Not Found: /reservations/make_reservation
2011-10-19 16:45:22,441 [ERROR] django.request: Internal Server Error: /clubs/edit_court_setup/8/8/
Traceback (most recent call last):
  File "/home/luka/etc/saion/ht_si/env/lib/python2.7/site-packages/django/core/handlers/base.py", line 111, in get_response
    response = callback(request, *callback_args, **callback_kwargs)
  File "/home/luka/etc/saion/ht_si/env/lib/python2.7/site-packages/django/contrib/auth/decorators.py", line 23, in _wrapped_view
    return view_func(request, *args, **kwargs)
  File "/home/luka/etc/saion/ht_si/env/ht/clubs/views.py", line 114, in edit_court_setup
    context_instance=RequestContext(request))
  File "/home/luka/etc/saion/ht_si/env/lib/python2.7/site-packages/django/shortcuts/__init__.py", line 20, in render_to_response
    return HttpResponse(loader.render_to_string(*args, **kwargs), **httpresponse_kwargs)
  File "/home/luka/etc/saion/ht_si/env/lib/python2.7/site-packages/django/template/loader.py", line 188, in render_to_string
    return t.render(context_instance)
  File "/home/luka/etc/saion/ht_si/env/lib/python2.7/site-packages/django/template/base.py", line 123, in render
    return self._render(context)
  File "/home/luka/etc/saion/ht_si/env/lib/python2.7/site-packages/django/test/utils.py", line 60, in instrumented_test_render
    return self.nodelist.render(context)
  File "/home/luka/etc/saion/ht_si/env/lib/python2.7/site-packages/django/template/base.py", line 744, in render
    bits.append(self.render_node(node, context))
  File "/home/luka/etc/saion/ht_si/env/lib/python2.7/site-packages/django/template/debug.py", line 73, in render_node
    result = node.render(context)
  File "/home/luka/etc/saion/ht_si/env/lib/python2.7/site-packages/django/template/loader_tags.py", line 127, in render
    return compiled_parent._render(context)
  File "/home/luka/etc/saion/ht_si/env/lib/python2.7/site-packages/django/test/utils.py", line 60, in instrumented_test_render
    return self.nodelist.render(context)
  File "/home/luka/etc/saion/ht_si/env/lib/python2.7/site-packages/django/template/base.py", line 744, in render
    bits.append(self.render_node(node, context))
  File "/home/luka/etc/saion/ht_si/env/lib/python2.7/site-packages/django/template/debug.py", line 73, in render_node
    result = node.render(context)
  File "/home/luka/etc/saion/ht_si/env/lib/python2.7/site-packages/django/template/defaulttags.py", line 311, in render
    return self.nodelist_true.render(context)
  File "/home/luka/etc/saion/ht_si/env/lib/python2.7/site-packages/django/template/base.py", line 744, in render
    bits.append(self.render_node(node, context))
  File "/home/luka/etc/saion/ht_si/env/lib/python2.7/site-packages/django/template/debug.py", line 73, in render_node
    result = node.render(context)
  File "/home/luka/etc/saion/ht_si/env/lib/python2.7/site-packages/django/template/loader_tags.py", line 64, in render
    result = block.nodelist.render(context)
  File "/home/luka/etc/saion/ht_si/env/lib/python2.7/site-packages/django/template/base.py", line 744, in render
    bits.append(self.render_node(node, context))
  File "/home/luka/etc/saion/ht_si/env/lib/python2.7/site-packages/django/template/debug.py", line 73, in render_node
    result = node.render(context)
  File "/home/luka/etc/saion/ht_si/env/lib/python2.7/site-packages/django/template/defaulttags.py", line 227, in render
    nodelist.append(node.render(context))
  File "/home/luka/etc/saion/ht_si/env/lib/python2.7/site-packages/django/template/defaulttags.py", line 311, in render
    return self.nodelist_true.render(context)
  File "/home/luka/etc/saion/ht_si/env/lib/python2.7/site-packages/django/template/base.py", line 744, in render
    bits.append(self.render_node(node, context))
  File "/home/luka/etc/saion/ht_si/env/lib/python2.7/site-packages/django/template/debug.py", line 73, in render_node
    result = node.render(context)
  File "/home/luka/etc/saion/ht_si/env/lib/python2.7/site-packages/django/template/defaulttags.py", line 313, in render
    return self.nodelist_false.render(context)
  File "/home/luka/etc/saion/ht_si/env/lib/python2.7/site-packages/django/template/base.py", line 744, in render
    bits.append(self.render_node(node, context))
  File "/home/luka/etc/saion/ht_si/env/lib/python2.7/site-packages/django/template/debug.py", line 73, in render_node
    result = node.render(context)
  File "/home/luka/etc/saion/ht_si/env/lib/python2.7/site-packages/django/template/defaulttags.py", line 227, in render
    nodelist.append(node.render(context))
  File "/home/luka/etc/saion/ht_si/env/lib/python2.7/site-packages/django/template/base.py", line 921, in render
    dict = func(*args)
  File "/home/luka/etc/saion/ht_si/env/ht/clubs/templatetags/vacancy_tags.py", line 47, in vacancy_prices_per_day
    vs = Vacancy.objects.filter (court__id=court_id) \
TemplateSyntaxError: Caught AttributeError while rendering: 'dict' object has no attribute 'id'
2011-10-20 11:55:42,856 [ERROR] django.request: Internal Server Error: /accounts/register
Traceback (most recent call last):
  File "/home/luka/etc/saion/ht_si/env/lib/python2.7/site-packages/django/core/handlers/base.py", line 111, in get_response
    response = callback(request, *callback_args, **callback_kwargs)
  File "/home/luka/etc/saion/ht_si/env/ht/accounts/views.py", line 26, in register
    password=form.cleaned_data['pass1'])
  File "/home/luka/etc/saion/ht_si/env/lib/python2.7/site-packages/django/contrib/auth/models.py", line 136, in create_user
    user.save(using=self._db)
  File "/home/luka/etc/saion/ht_si/env/lib/python2.7/site-packages/django/db/models/base.py", line 460, in save
    self.save_base(using=using, force_insert=force_insert, force_update=force_update)
  File "/home/luka/etc/saion/ht_si/env/lib/python2.7/site-packages/django/db/models/base.py", line 553, in save_base
    result = manager._insert(values, return_id=update_pk, using=using)
  File "/home/luka/etc/saion/ht_si/env/lib/python2.7/site-packages/django/db/models/manager.py", line 195, in _insert
    return insert_query(self.model, values, **kwargs)
  File "/home/luka/etc/saion/ht_si/env/lib/python2.7/site-packages/django/db/models/query.py", line 1436, in insert_query
    return query.get_compiler(using=using).execute_sql(return_id)
  File "/home/luka/etc/saion/ht_si/env/lib/python2.7/site-packages/django/db/models/sql/compiler.py", line 791, in execute_sql
    cursor = super(SQLInsertCompiler, self).execute_sql(None)
  File "/home/luka/etc/saion/ht_si/env/lib/python2.7/site-packages/django/db/models/sql/compiler.py", line 735, in execute_sql
    cursor.execute(sql, params)
  File "/home/luka/etc/saion/ht_si/env/lib/python2.7/site-packages/django/db/backends/postgresql_psycopg2/base.py", line 44, in execute
    return self.cursor.execute(query, args)
IntegrityError: duplicate key value violates unique constraint "auth_user_username_key"
DETAIL:  Key (username)=(club@nowhere.si) already exists.

2011-10-20 12:00:04,382 [ERROR] django.request: Internal Server Error: /accounts/register
Traceback (most recent call last):
  File "/home/luka/etc/saion/ht_si/env/lib/python2.7/site-packages/django/core/handlers/base.py", line 111, in get_response
    response = callback(request, *callback_args, **callback_kwargs)
  File "/home/luka/etc/saion/ht_si/env/ht/accounts/views.py", line 26, in register
    password=form.cleaned_data['pass1'])
  File "/home/luka/etc/saion/ht_si/env/lib/python2.7/site-packages/django/contrib/auth/models.py", line 136, in create_user
    user.save(using=self._db)
  File "/home/luka/etc/saion/ht_si/env/lib/python2.7/site-packages/django/db/models/base.py", line 460, in save
    self.save_base(using=using, force_insert=force_insert, force_update=force_update)
  File "/home/luka/etc/saion/ht_si/env/lib/python2.7/site-packages/django/db/models/base.py", line 553, in save_base
    result = manager._insert(values, return_id=update_pk, using=using)
  File "/home/luka/etc/saion/ht_si/env/lib/python2.7/site-packages/django/db/models/manager.py", line 195, in _insert
    return insert_query(self.model, values, **kwargs)
  File "/home/luka/etc/saion/ht_si/env/lib/python2.7/site-packages/django/db/models/query.py", line 1436, in insert_query
    return query.get_compiler(using=using).execute_sql(return_id)
  File "/home/luka/etc/saion/ht_si/env/lib/python2.7/site-packages/django/db/models/sql/compiler.py", line 791, in execute_sql
    cursor = super(SQLInsertCompiler, self).execute_sql(None)
  File "/home/luka/etc/saion/ht_si/env/lib/python2.7/site-packages/django/db/models/sql/compiler.py", line 735, in execute_sql
    cursor.execute(sql, params)
  File "/home/luka/etc/saion/ht_si/env/lib/python2.7/site-packages/django/db/backends/postgresql_psycopg2/base.py", line 44, in execute
    return self.cursor.execute(query, args)
IntegrityError: duplicate key value violates unique constraint "auth_user_username_key"
DETAIL:  Key (username)=(club@nowhere.si) already exists.

2011-10-20 12:00:31,819 [ERROR] django.request: Internal Server Error: /accounts/register
Traceback (most recent call last):
  File "/home/luka/etc/saion/ht_si/env/lib/python2.7/site-packages/django/core/handlers/base.py", line 111, in get_response
    response = callback(request, *callback_args, **callback_kwargs)
  File "/home/luka/etc/saion/ht_si/env/ht/accounts/views.py", line 26, in register
    password=form.cleaned_data['pass1'])
  File "/home/luka/etc/saion/ht_si/env/lib/python2.7/site-packages/django/contrib/auth/models.py", line 136, in create_user
    user.save(using=self._db)
  File "/home/luka/etc/saion/ht_si/env/lib/python2.7/site-packages/django/db/models/base.py", line 460, in save
    self.save_base(using=using, force_insert=force_insert, force_update=force_update)
  File "/home/luka/etc/saion/ht_si/env/lib/python2.7/site-packages/django/db/models/base.py", line 553, in save_base
    result = manager._insert(values, return_id=update_pk, using=using)
  File "/home/luka/etc/saion/ht_si/env/lib/python2.7/site-packages/django/db/models/manager.py", line 195, in _insert
    return insert_query(self.model, values, **kwargs)
  File "/home/luka/etc/saion/ht_si/env/lib/python2.7/site-packages/django/db/models/query.py", line 1436, in insert_query
    return query.get_compiler(using=using).execute_sql(return_id)
  File "/home/luka/etc/saion/ht_si/env/lib/python2.7/site-packages/django/db/models/sql/compiler.py", line 791, in execute_sql
    cursor = super(SQLInsertCompiler, self).execute_sql(None)
  File "/home/luka/etc/saion/ht_si/env/lib/python2.7/site-packages/django/db/models/sql/compiler.py", line 735, in execute_sql
    cursor.execute(sql, params)
  File "/home/luka/etc/saion/ht_si/env/lib/python2.7/site-packages/django/db/backends/postgresql_psycopg2/base.py", line 44, in execute
    return self.cursor.execute(query, args)
IntegrityError: duplicate key value violates unique constraint "auth_user_username_key"
DETAIL:  Key (username)=(club@nowhere.si) already exists.

2011-10-20 12:02:01,519 [ERROR] django.request: Internal Server Error: /accounts/register
Traceback (most recent call last):
  File "/home/luka/etc/saion/ht_si/env/lib/python2.7/site-packages/django/core/handlers/base.py", line 111, in get_response
    response = callback(request, *callback_args, **callback_kwargs)
  File "/home/luka/etc/saion/ht_si/env/ht/accounts/views.py", line 26, in register
    password=form.cleaned_data['pass1'])
  File "/home/luka/etc/saion/ht_si/env/lib/python2.7/site-packages/django/contrib/auth/models.py", line 136, in create_user
    user.save(using=self._db)
  File "/home/luka/etc/saion/ht_si/env/lib/python2.7/site-packages/django/db/models/base.py", line 460, in save
    self.save_base(using=using, force_insert=force_insert, force_update=force_update)
  File "/home/luka/etc/saion/ht_si/env/lib/python2.7/site-packages/django/db/models/base.py", line 553, in save_base
    result = manager._insert(values, return_id=update_pk, using=using)
  File "/home/luka/etc/saion/ht_si/env/lib/python2.7/site-packages/django/db/models/manager.py", line 195, in _insert
    return insert_query(self.model, values, **kwargs)
  File "/home/luka/etc/saion/ht_si/env/lib/python2.7/site-packages/django/db/models/query.py", line 1436, in insert_query
    return query.get_compiler(using=using).execute_sql(return_id)
  File "/home/luka/etc/saion/ht_si/env/lib/python2.7/site-packages/django/db/models/sql/compiler.py", line 791, in execute_sql
    cursor = super(SQLInsertCompiler, self).execute_sql(None)
  File "/home/luka/etc/saion/ht_si/env/lib/python2.7/site-packages/django/db/models/sql/compiler.py", line 735, in execute_sql
    cursor.execute(sql, params)
  File "/home/luka/etc/saion/ht_si/env/lib/python2.7/site-packages/django/db/backends/postgresql_psycopg2/base.py", line 44, in execute
    return self.cursor.execute(query, args)
IntegrityError: duplicate key value violates unique constraint "auth_user_username_key"
DETAIL:  Key (username)=(club@nowhere.si) already exists.

2011-10-20 12:06:17,475 [ERROR] django.request: Internal Server Error: /accounts/register
Traceback (most recent call last):
  File "/home/luka/etc/saion/ht_si/env/lib/python2.7/site-packages/django/core/handlers/base.py", line 111, in get_response
    response = callback(request, *callback_args, **callback_kwargs)
  File "/home/luka/etc/saion/ht_si/env/ht/accounts/views.py", line 20, in register
    if form.is_valid ( ):
  File "/home/luka/etc/saion/ht_si/env/lib/python2.7/site-packages/django/forms/forms.py", line 121, in is_valid
    return self.is_bound and not bool(self.errors)
  File "/home/luka/etc/saion/ht_si/env/lib/python2.7/site-packages/django/forms/forms.py", line 112, in _get_errors
    self.full_clean()
  File "/home/luka/etc/saion/ht_si/env/lib/python2.7/site-packages/django/forms/forms.py", line 267, in full_clean
    self._clean_fields()
  File "/home/luka/etc/saion/ht_si/env/lib/python2.7/site-packages/django/forms/forms.py", line 287, in _clean_fields
    value = getattr(self, 'clean_%s' % name)()
  File "/home/luka/etc/saion/ht_si/env/ht/accounts/forms.py", line 24, in clean_email
    try:
  File "/home/luka/etc/saion/ht_si/env/ht/accounts/forms.py", line 24, in clean_email
    try:
  File "/usr/lib/python2.7/bdb.py", line 48, in trace_dispatch
    return self.dispatch_line(frame)
  File "/usr/lib/python2.7/bdb.py", line 67, in dispatch_line
    if self.quitting: raise BdbQuit
BdbQuit
2011-10-20 12:06:21,992 [ERROR] django.request: Internal Server Error: /accounts/register
Traceback (most recent call last):
  File "/home/luka/etc/saion/ht_si/env/lib/python2.7/site-packages/django/core/handlers/base.py", line 111, in get_response
    response = callback(request, *callback_args, **callback_kwargs)
  File "/home/luka/etc/saion/ht_si/env/ht/accounts/views.py", line 20, in register
    if form.is_valid ( ):
  File "/home/luka/etc/saion/ht_si/env/lib/python2.7/site-packages/django/forms/forms.py", line 121, in is_valid
    return self.is_bound and not bool(self.errors)
  File "/home/luka/etc/saion/ht_si/env/lib/python2.7/site-packages/django/forms/forms.py", line 112, in _get_errors
    self.full_clean()
  File "/home/luka/etc/saion/ht_si/env/lib/python2.7/site-packages/django/forms/forms.py", line 267, in full_clean
    self._clean_fields()
  File "/home/luka/etc/saion/ht_si/env/lib/python2.7/site-packages/django/forms/forms.py", line 287, in _clean_fields
    value = getattr(self, 'clean_%s' % name)()
  File "/home/luka/etc/saion/ht_si/env/ht/accounts/forms.py", line 24, in clean_email
    try:
  File "/home/luka/etc/saion/ht_si/env/ht/accounts/forms.py", line 24, in clean_email
    try:
  File "/usr/lib/python2.7/bdb.py", line 48, in trace_dispatch
    return self.dispatch_line(frame)
  File "/usr/lib/python2.7/bdb.py", line 67, in dispatch_line
    if self.quitting: raise BdbQuit
BdbQuit
2011-10-20 12:06:24,216 [ERROR] django.request: Internal Server Error: /accounts/register
Traceback (most recent call last):
  File "/home/luka/etc/saion/ht_si/env/lib/python2.7/site-packages/django/core/handlers/base.py", line 111, in get_response
    response = callback(request, *callback_args, **callback_kwargs)
  File "/home/luka/etc/saion/ht_si/env/ht/accounts/views.py", line 20, in register
    if form.is_valid ( ):
  File "/home/luka/etc/saion/ht_si/env/lib/python2.7/site-packages/django/forms/forms.py", line 121, in is_valid
    return self.is_bound and not bool(self.errors)
  File "/home/luka/etc/saion/ht_si/env/lib/python2.7/site-packages/django/forms/forms.py", line 112, in _get_errors
    self.full_clean()
  File "/home/luka/etc/saion/ht_si/env/lib/python2.7/site-packages/django/forms/forms.py", line 267, in full_clean
    self._clean_fields()
  File "/home/luka/etc/saion/ht_si/env/lib/python2.7/site-packages/django/forms/forms.py", line 287, in _clean_fields
    value = getattr(self, 'clean_%s' % name)()
  File "/home/luka/etc/saion/ht_si/env/ht/accounts/forms.py", line 24, in clean_email
    try:
  File "/home/luka/etc/saion/ht_si/env/ht/accounts/forms.py", line 24, in clean_email
    try:
  File "/usr/lib/python2.7/bdb.py", line 48, in trace_dispatch
    return self.dispatch_line(frame)
  File "/usr/lib/python2.7/bdb.py", line 67, in dispatch_line
    if self.quitting: raise BdbQuit
BdbQuit
2011-10-20 12:07:17,619 [ERROR] django.request: Internal Server Error: /accounts/register
Traceback (most recent call last):
  File "/home/luka/etc/saion/ht_si/env/lib/python2.7/site-packages/django/core/handlers/base.py", line 111, in get_response
    response = callback(request, *callback_args, **callback_kwargs)
  File "/home/luka/etc/saion/ht_si/env/ht/accounts/views.py", line 20, in register
    if form.is_valid ( ):
  File "/home/luka/etc/saion/ht_si/env/lib/python2.7/site-packages/django/forms/forms.py", line 121, in is_valid
    return self.is_bound and not bool(self.errors)
  File "/home/luka/etc/saion/ht_si/env/lib/python2.7/site-packages/django/forms/forms.py", line 112, in _get_errors
    self.full_clean()
  File "/home/luka/etc/saion/ht_si/env/lib/python2.7/site-packages/django/forms/forms.py", line 267, in full_clean
    self._clean_fields()
  File "/home/luka/etc/saion/ht_si/env/lib/python2.7/site-packages/django/forms/forms.py", line 287, in _clean_fields
    value = getattr(self, 'clean_%s' % name)()
  File "/home/luka/etc/saion/ht_si/env/ht/accounts/forms.py", line 26, in clean_email
    except DoesNotExist:
NameError: global name 'DoesNotExist' is not defined
2011-10-20 12:07:17,795 [ERROR] django.request: Internal Server Error: /accounts/register
Traceback (most recent call last):
  File "/home/luka/etc/saion/ht_si/env/lib/python2.7/site-packages/django/core/handlers/base.py", line 111, in get_response
    response = callback(request, *callback_args, **callback_kwargs)
  File "/home/luka/etc/saion/ht_si/env/ht/accounts/views.py", line 20, in register
    if form.is_valid ( ):
  File "/home/luka/etc/saion/ht_si/env/lib/python2.7/site-packages/django/forms/forms.py", line 121, in is_valid
    return self.is_bound and not bool(self.errors)
  File "/home/luka/etc/saion/ht_si/env/lib/python2.7/site-packages/django/forms/forms.py", line 112, in _get_errors
    self.full_clean()
  File "/home/luka/etc/saion/ht_si/env/lib/python2.7/site-packages/django/forms/forms.py", line 267, in full_clean
    self._clean_fields()
  File "/home/luka/etc/saion/ht_si/env/lib/python2.7/site-packages/django/forms/forms.py", line 287, in _clean_fields
    value = getattr(self, 'clean_%s' % name)()
  File "/home/luka/etc/saion/ht_si/env/ht/accounts/forms.py", line 26, in clean_email
    except DoesNotExist:
NameError: global name 'DoesNotExist' is not defined
2011-10-20 12:07:17,892 [ERROR] django.request: Internal Server Error: /accounts/register
Traceback (most recent call last):
  File "/home/luka/etc/saion/ht_si/env/lib/python2.7/site-packages/django/core/handlers/base.py", line 111, in get_response
    response = callback(request, *callback_args, **callback_kwargs)
  File "/home/luka/etc/saion/ht_si/env/ht/accounts/views.py", line 20, in register
    if form.is_valid ( ):
  File "/home/luka/etc/saion/ht_si/env/lib/python2.7/site-packages/django/forms/forms.py", line 121, in is_valid
    return self.is_bound and not bool(self.errors)
  File "/home/luka/etc/saion/ht_si/env/lib/python2.7/site-packages/django/forms/forms.py", line 112, in _get_errors
    self.full_clean()
  File "/home/luka/etc/saion/ht_si/env/lib/python2.7/site-packages/django/forms/forms.py", line 267, in full_clean
    self._clean_fields()
  File "/home/luka/etc/saion/ht_si/env/lib/python2.7/site-packages/django/forms/forms.py", line 287, in _clean_fields
    value = getattr(self, 'clean_%s' % name)()
  File "/home/luka/etc/saion/ht_si/env/ht/accounts/forms.py", line 26, in clean_email
    except DoesNotExist:
NameError: global name 'DoesNotExist' is not defined
2011-10-20 12:10:04,766 [ERROR] django.request: Internal Server Error: /accounts/register
Traceback (most recent call last):
  File "/home/luka/etc/saion/ht_si/env/lib/python2.7/site-packages/django/core/handlers/base.py", line 111, in get_response
    response = callback(request, *callback_args, **callback_kwargs)
  File "/home/luka/etc/saion/ht_si/env/ht/accounts/views.py", line 20, in register
    if form.is_valid ( ):
  File "/home/luka/etc/saion/ht_si/env/lib/python2.7/site-packages/django/forms/forms.py", line 121, in is_valid
    return self.is_bound and not bool(self.errors)
  File "/home/luka/etc/saion/ht_si/env/lib/python2.7/site-packages/django/forms/forms.py", line 112, in _get_errors
    self.full_clean()
  File "/home/luka/etc/saion/ht_si/env/lib/python2.7/site-packages/django/forms/forms.py", line 267, in full_clean
    self._clean_fields()
  File "/home/luka/etc/saion/ht_si/env/lib/python2.7/site-packages/django/forms/forms.py", line 287, in _clean_fields
    value = getattr(self, 'clean_%s' % name)()
  File "/home/luka/etc/saion/ht_si/env/ht/accounts/forms.py", line 29, in clean_email
    return data
  File "/home/luka/etc/saion/ht_si/env/ht/accounts/forms.py", line 29, in clean_email
    return data
  File "/usr/lib/python2.7/bdb.py", line 48, in trace_dispatch
    return self.dispatch_line(frame)
  File "/usr/lib/python2.7/bdb.py", line 67, in dispatch_line
    if self.quitting: raise BdbQuit
BdbQuit
2011-10-20 12:10:27,919 [ERROR] django.request: Internal Server Error: /accounts/register
Traceback (most recent call last):
  File "/home/luka/etc/saion/ht_si/env/lib/python2.7/site-packages/django/core/handlers/base.py", line 111, in get_response
    response = callback(request, *callback_args, **callback_kwargs)
  File "/home/luka/etc/saion/ht_si/env/ht/accounts/views.py", line 26, in register
    password=form.cleaned_data['pass1'])
  File "/home/luka/etc/saion/ht_si/env/lib/python2.7/site-packages/django/contrib/auth/models.py", line 136, in create_user
    user.save(using=self._db)
  File "/home/luka/etc/saion/ht_si/env/lib/python2.7/site-packages/django/db/models/base.py", line 460, in save
    self.save_base(using=using, force_insert=force_insert, force_update=force_update)
  File "/home/luka/etc/saion/ht_si/env/lib/python2.7/site-packages/django/db/models/base.py", line 553, in save_base
    result = manager._insert(values, return_id=update_pk, using=using)
  File "/home/luka/etc/saion/ht_si/env/lib/python2.7/site-packages/django/db/models/manager.py", line 195, in _insert
    return insert_query(self.model, values, **kwargs)
  File "/home/luka/etc/saion/ht_si/env/lib/python2.7/site-packages/django/db/models/query.py", line 1436, in insert_query
    return query.get_compiler(using=using).execute_sql(return_id)
  File "/home/luka/etc/saion/ht_si/env/lib/python2.7/site-packages/django/db/models/sql/compiler.py", line 791, in execute_sql
    cursor = super(SQLInsertCompiler, self).execute_sql(None)
  File "/home/luka/etc/saion/ht_si/env/lib/python2.7/site-packages/django/db/models/sql/compiler.py", line 735, in execute_sql
    cursor.execute(sql, params)
  File "/home/luka/etc/saion/ht_si/env/lib/python2.7/site-packages/django/db/backends/postgresql_psycopg2/base.py", line 44, in execute
    return self.cursor.execute(query, args)
IntegrityError: duplicate key value violates unique constraint "auth_user_username_key"
DETAIL:  Key (username)=(club@nowhere.si) already exists.

2011-10-20 12:10:38,342 [ERROR] django.request: Internal Server Error: /accounts/register
Traceback (most recent call last):
  File "/home/luka/etc/saion/ht_si/env/lib/python2.7/site-packages/django/core/handlers/base.py", line 111, in get_response
    response = callback(request, *callback_args, **callback_kwargs)
  File "/home/luka/etc/saion/ht_si/env/ht/accounts/views.py", line 26, in register
    password=form.cleaned_data['pass1'])
  File "/home/luka/etc/saion/ht_si/env/lib/python2.7/site-packages/django/contrib/auth/models.py", line 136, in create_user
    user.save(using=self._db)
  File "/home/luka/etc/saion/ht_si/env/lib/python2.7/site-packages/django/db/models/base.py", line 460, in save
    self.save_base(using=using, force_insert=force_insert, force_update=force_update)
  File "/home/luka/etc/saion/ht_si/env/lib/python2.7/site-packages/django/db/models/base.py", line 553, in save_base
    result = manager._insert(values, return_id=update_pk, using=using)
  File "/home/luka/etc/saion/ht_si/env/lib/python2.7/site-packages/django/db/models/manager.py", line 195, in _insert
    return insert_query(self.model, values, **kwargs)
  File "/home/luka/etc/saion/ht_si/env/lib/python2.7/site-packages/django/db/models/query.py", line 1436, in insert_query
    return query.get_compiler(using=using).execute_sql(return_id)
  File "/home/luka/etc/saion/ht_si/env/lib/python2.7/site-packages/django/db/models/sql/compiler.py", line 791, in execute_sql
    cursor = super(SQLInsertCompiler, self).execute_sql(None)
  File "/home/luka/etc/saion/ht_si/env/lib/python2.7/site-packages/django/db/models/sql/compiler.py", line 735, in execute_sql
    cursor.execute(sql, params)
  File "/home/luka/etc/saion/ht_si/env/lib/python2.7/site-packages/django/db/backends/postgresql_psycopg2/base.py", line 44, in execute
    return self.cursor.execute(query, args)
IntegrityError: duplicate key value violates unique constraint "auth_user_username_key"
DETAIL:  Key (username)=(club@nowhere.si) already exists.

2011-10-20 12:12:20,656 [ERROR] django.request: Internal Server Error: /accounts/register
Traceback (most recent call last):
  File "/home/luka/etc/saion/ht_si/env/lib/python2.7/site-packages/django/core/handlers/base.py", line 111, in get_response
    response = callback(request, *callback_args, **callback_kwargs)
  File "/home/luka/etc/saion/ht_si/env/ht/accounts/views.py", line 26, in register
    password=form.cleaned_data['pass1'])
  File "/home/luka/etc/saion/ht_si/env/lib/python2.7/site-packages/django/contrib/auth/models.py", line 136, in create_user
    user.save(using=self._db)
  File "/home/luka/etc/saion/ht_si/env/lib/python2.7/site-packages/django/db/models/base.py", line 460, in save
    self.save_base(using=using, force_insert=force_insert, force_update=force_update)
  File "/home/luka/etc/saion/ht_si/env/lib/python2.7/site-packages/django/db/models/base.py", line 553, in save_base
    result = manager._insert(values, return_id=update_pk, using=using)
  File "/home/luka/etc/saion/ht_si/env/lib/python2.7/site-packages/django/db/models/manager.py", line 195, in _insert
    return insert_query(self.model, values, **kwargs)
  File "/home/luka/etc/saion/ht_si/env/lib/python2.7/site-packages/django/db/models/query.py", line 1436, in insert_query
    return query.get_compiler(using=using).execute_sql(return_id)
  File "/home/luka/etc/saion/ht_si/env/lib/python2.7/site-packages/django/db/models/sql/compiler.py", line 791, in execute_sql
    cursor = super(SQLInsertCompiler, self).execute_sql(None)
  File "/home/luka/etc/saion/ht_si/env/lib/python2.7/site-packages/django/db/models/sql/compiler.py", line 735, in execute_sql
    cursor.execute(sql, params)
  File "/home/luka/etc/saion/ht_si/env/lib/python2.7/site-packages/django/db/backends/postgresql_psycopg2/base.py", line 44, in execute
    return self.cursor.execute(query, args)
IntegrityError: duplicate key value violates unique constraint "auth_user_username_key"
DETAIL:  Key (username)=(club@nowhere.si) already exists.

2011-10-20 14:18:02,467 [ERROR] django.request: Internal Server Error: /accounts/register
Traceback (most recent call last):
  File "/home/luka/etc/saion/ht_si/env/lib/python2.7/site-packages/django/core/handlers/base.py", line 111, in get_response
    response = callback(request, *callback_args, **callback_kwargs)
  File "/home/luka/etc/saion/ht_si/env/ht/accounts/views.py", line 34, in register
    login (request, new_user)
TypeError: login() takes exactly 1 argument (2 given)
2011-10-20 14:18:55,723 [ERROR] django.request: Internal Server Error: /accounts/edit_player_profile/7/
Traceback (most recent call last):
  File "/home/luka/etc/saion/ht_si/env/lib/python2.7/site-packages/django/core/handlers/base.py", line 129, in get_response
    raise ValueError("The view %s.%s didn't return an HttpResponse object." % (callback.__module__, view_name))
ValueError: The view accounts.views.edit_player_profile didn't return an HttpResponse object.
2011-10-20 14:51:52,950 [WARNING] django.request: Not Found: /accounts/edit_player_profile
2011-10-20 14:51:53,195 [WARNING] django.request: Not Found: /accounts/accounts.views.edit_player_profile
2011-10-20 14:54:36,303 [WARNING] django.request: Not Found: /accounts/edit_player_profile
2011-10-20 14:54:36,431 [ERROR] django.request: Internal Server Error: /accounts/login
Traceback (most recent call last):
  File "/home/luka/etc/saion/ht_si/env/lib/python2.7/site-packages/django/core/handlers/base.py", line 111, in get_response
    response = callback(request, *callback_args, **callback_kwargs)
  File "/home/luka/etc/saion/ht_si/env/ht/accounts/views.py", line 90, in login
    return auth.views.login (request, 'accounts/login.html')
AttributeError: 'module' object has no attribute 'views'
2011-10-20 14:54:36,606 [WARNING] django.request: Not Found: /accounts/accounts.views.edit_player_profile
2011-10-20 14:55:34,823 [WARNING] django.request: Not Found: /accounts/edit_player_profile
2011-10-20 14:55:35,189 [WARNING] django.request: Not Found: /accounts/accounts.views.edit_player_profile
2011-10-20 14:59:20,196 [WARNING] django.request: Not Found: /accounts/edit_player_profile
2011-10-20 14:59:20,622 [WARNING] django.request: Not Found: /accounts/accounts.views.edit_player_profile
2011-10-20 14:59:43,031 [WARNING] django.request: Not Found: /accounts/edit_player_profile
2011-10-20 15:02:06,638 [WARNING] django.request: Not Found: /accounts/accounts.views.edit_player_profile
2011-10-20 17:45:45,097 [WARNING] django.request: Not Found: /accounts/edit_player_profile
2011-10-20 18:13:12,058 [WARNING] django.request: Not Found: /accounts/accounts.views.edit_player_profile
2011-10-20 18:13:31,021 [WARNING] django.request: Not Found: /accounts/edit_player_profile
2011-10-20 18:14:29,725 [WARNING] django.request: Not Found: /accounts/accounts.views.edit_player_profile
2011-10-20 18:29:09,823 [WARNING] django.request: Not Found: /accounts/edit_player_profile
2011-10-20 18:29:10,332 [WARNING] django.request: Not Found: /accounts/accounts.views.edit_player_profile
2011-10-20 18:32:35,419 [WARNING] django.request: Not Found: /accounts/edit_player_profile
2011-10-20 18:32:35,931 [WARNING] django.request: Not Found: /accounts/accounts.views.edit_player_profile
2011-10-20 18:33:20,586 [WARNING] django.request: Not Found: /accounts/edit_player_profile
2011-10-20 18:33:21,142 [WARNING] django.request: Not Found: /accounts/accounts.views.edit_player_profile
2011-10-20 18:34:54,864 [WARNING] django.request: Not Found: /accounts/edit_player_profile
2011-10-20 18:34:55,202 [ERROR] django.request: Internal Server Error: /accounts/logout
Traceback (most recent call last):
  File "/home/luka/etc/saion/ht_si/env/lib/python2.7/site-packages/django/core/handlers/base.py", line 111, in get_response
    response = callback(request, *callback_args, **callback_kwargs)
  File "/home/luka/etc/saion/ht_si/env/ht/accounts/views.py", line 103, in logout
    return auth.logout (request, next_page='/')
TypeError: logout() got an unexpected keyword argument 'next_page'
2011-10-20 18:34:55,465 [WARNING] django.request: Not Found: /accounts/accounts.views.edit_player_profile
2011-10-20 18:35:51,077 [WARNING] django.request: Not Found: /accounts/edit_player_profile
2011-10-20 18:35:51,691 [WARNING] django.request: Not Found: /accounts/accounts.views.edit_player_profile
2011-10-20 18:37:31,563 [WARNING] django.request: Not Found: /accounts/edit_player_profile
2011-10-20 18:37:32,188 [WARNING] django.request: Not Found: /accounts/accounts.views.edit_player_profile
2011-10-20 18:38:00,934 [WARNING] django.request: Not Found: /accounts/edit_player_profile
2011-10-20 18:38:01,576 [WARNING] django.request: Not Found: /accounts/accounts.views.edit_player_profile
2011-10-20 19:04:18,509 [WARNING] django.request: Not Found: /accounts/edit_player_profile
2011-10-20 19:04:19,185 [WARNING] django.request: Not Found: /accounts/accounts.views.edit_player_profile
2011-10-20 19:11:56,302 [WARNING] django.request: Not Found: /accounts/edit_player_profile
2011-10-20 19:11:56,979 [WARNING] django.request: Not Found: /accounts/accounts.views.edit_player_profile
2011-10-20 19:16:15,062 [WARNING] django.request: Not Found: /accounts/edit_player_profile
2011-10-20 19:16:15,753 [WARNING] django.request: Not Found: /accounts/accounts.views.edit_player_profile
2011-10-20 19:17:49,311 [WARNING] django.request: Not Found: /accounts/edit_player_profile
2011-10-20 19:17:50,008 [WARNING] django.request: Not Found: /accounts/accounts.views.edit_player_profile
2011-10-20 19:19:12,509 [WARNING] django.request: Not Found: /accounts/edit_player_profile
2011-10-20 19:19:13,192 [WARNING] django.request: Not Found: /accounts/accounts.views.edit_player_profile
2011-10-20 19:20:23,556 [WARNING] django.request: Not Found: /accounts/edit_player_profile
2011-10-20 19:20:23,729 [ERROR] django.request: Internal Server Error: /accounts/edit_player_profile
Traceback (most recent call last):
  File "/home/luka/etc/saion/ht_si/env/lib/python2.7/site-packages/django/core/handlers/base.py", line 111, in get_response
    response = callback(request, *callback_args, **callback_kwargs)
  File "/home/luka/etc/saion/ht_si/env/lib/python2.7/site-packages/django/contrib/auth/decorators.py", line 23, in _wrapped_view
    return view_func(request, *args, **kwargs)
  File "/home/luka/etc/saion/ht_si/env/ht/accounts/views.py", line 67, in edit_player_profile
    user.save ( )
  File "/home/luka/etc/saion/ht_si/env/lib/python2.7/site-packages/django/db/models/base.py", line 460, in save
    self.save_base(using=using, force_insert=force_insert, force_update=force_update)
  File "/home/luka/etc/saion/ht_si/env/lib/python2.7/site-packages/django/db/models/base.py", line 526, in save_base
    rows = manager.using(using).filter(pk=pk_val)._update(values)
  File "/home/luka/etc/saion/ht_si/env/lib/python2.7/site-packages/django/db/models/query.py", line 491, in _update
    return query.get_compiler(self.db).execute_sql(None)
  File "/home/luka/etc/saion/ht_si/env/lib/python2.7/site-packages/django/db/models/sql/compiler.py", line 869, in execute_sql
    cursor = super(SQLUpdateCompiler, self).execute_sql(result_type)
  File "/home/luka/etc/saion/ht_si/env/lib/python2.7/site-packages/django/db/models/sql/compiler.py", line 735, in execute_sql
    cursor.execute(sql, params)
  File "/home/luka/etc/saion/ht_si/env/lib/python2.7/site-packages/django/db/backends/postgresql_psycopg2/base.py", line 44, in execute
    return self.cursor.execute(query, args)
DatabaseError: value too long for type character varying(30)

2011-10-20 19:20:24,247 [WARNING] django.request: Not Found: /accounts/accounts.views.edit_player_profile
2011-10-20 19:21:10,443 [WARNING] django.request: Not Found: /accounts/edit_player_profile
2011-10-20 19:21:11,105 [WARNING] django.request: Not Found: /accounts/accounts.views.edit_player_profile
2011-10-20 19:25:21,644 [WARNING] django.request: Not Found: /accounts/edit_player_profile
2011-10-20 19:25:21,807 [ERROR] django.request: Internal Server Error: /accounts/edit_player_profile
Traceback (most recent call last):
  File "/home/luka/etc/saion/ht_si/env/lib/python2.7/site-packages/django/core/handlers/base.py", line 111, in get_response
    response = callback(request, *callback_args, **callback_kwargs)
  File "/home/luka/etc/saion/ht_si/env/lib/python2.7/site-packages/django/contrib/auth/decorators.py", line 23, in _wrapped_view
    return view_func(request, *args, **kwargs)
  File "/home/luka/etc/saion/ht_si/env/ht/accounts/views.py", line 63, in edit_player_profile
    if form.is_valid ( ):
  File "/home/luka/etc/saion/ht_si/env/lib/python2.7/site-packages/django/forms/forms.py", line 121, in is_valid
    return self.is_bound and not bool(self.errors)
  File "/home/luka/etc/saion/ht_si/env/lib/python2.7/site-packages/django/forms/forms.py", line 112, in _get_errors
    self.full_clean()
  File "/home/luka/etc/saion/ht_si/env/lib/python2.7/site-packages/django/forms/forms.py", line 267, in full_clean
    self._clean_fields()
  File "/home/luka/etc/saion/ht_si/env/lib/python2.7/site-packages/django/forms/forms.py", line 284, in _clean_fields
    value = field.clean(value)
  File "/home/luka/etc/saion/ht_si/env/lib/python2.7/site-packages/django/forms/fields.py", line 163, in clean
    value = self.to_python(value)
  File "/home/luka/etc/saion/ht_si/env/lib/python2.7/site-packages/django/forms/models.py", line 972, in to_python
    value = self.queryset.get(**{key: value})
  File "/home/luka/etc/saion/ht_si/env/lib/python2.7/site-packages/django/db/models/query.py", line 341, in get
    clone = self.filter(*args, **kwargs)
  File "/home/luka/etc/saion/ht_si/env/lib/python2.7/site-packages/django/db/models/query.py", line 550, in filter
    return self._filter_or_exclude(False, *args, **kwargs)
  File "/home/luka/etc/saion/ht_si/env/lib/python2.7/site-packages/django/db/models/query.py", line 568, in _filter_or_exclude
    clone.query.add_q(Q(*args, **kwargs))
  File "/home/luka/etc/saion/ht_si/env/lib/python2.7/site-packages/django/db/models/sql/query.py", line 1194, in add_q
    can_reuse=used_aliases, force_having=force_having)
  File "/home/luka/etc/saion/ht_si/env/lib/python2.7/site-packages/django/db/models/sql/query.py", line 1129, in add_filter
    connector)
  File "/home/luka/etc/saion/ht_si/env/lib/python2.7/site-packages/django/db/models/sql/where.py", line 67, in add
    value = obj.prepare(lookup_type, value)
  File "/home/luka/etc/saion/ht_si/env/lib/python2.7/site-packages/django/db/models/sql/where.py", line 316, in prepare
    return self.field.get_prep_lookup(lookup_type, value)
  File "/home/luka/etc/saion/ht_si/env/lib/python2.7/site-packages/django/db/models/fields/__init__.py", line 292, in get_prep_lookup
    return self.get_prep_value(value)
  File "/home/luka/etc/saion/ht_si/env/lib/python2.7/site-packages/django/db/models/fields/__init__.py", line 479, in get_prep_value
    return int(value)
TypeError: int() argument must be a string or a number, not 'User'
2011-10-20 19:25:22,334 [WARNING] django.request: Not Found: /accounts/accounts.views.edit_player_profile
2011-10-20 19:26:44,754 [WARNING] django.request: Not Found: /accounts/edit_player_profile
2011-10-20 19:26:44,915 [ERROR] django.request: Internal Server Error: /accounts/edit_player_profile
Traceback (most recent call last):
  File "/home/luka/etc/saion/ht_si/env/lib/python2.7/site-packages/django/core/handlers/base.py", line 111, in get_response
    response = callback(request, *callback_args, **callback_kwargs)
  File "/home/luka/etc/saion/ht_si/env/lib/python2.7/site-packages/django/contrib/auth/decorators.py", line 23, in _wrapped_view
    return view_func(request, *args, **kwargs)
  File "/home/luka/etc/saion/ht_si/env/ht/accounts/views.py", line 63, in edit_player_profile
    if form.is_valid ( ):
  File "/home/luka/etc/saion/ht_si/env/lib/python2.7/site-packages/django/forms/forms.py", line 121, in is_valid
    return self.is_bound and not bool(self.errors)
  File "/home/luka/etc/saion/ht_si/env/lib/python2.7/site-packages/django/forms/forms.py", line 112, in _get_errors
    self.full_clean()
  File "/home/luka/etc/saion/ht_si/env/lib/python2.7/site-packages/django/forms/forms.py", line 267, in full_clean
    self._clean_fields()
  File "/home/luka/etc/saion/ht_si/env/lib/python2.7/site-packages/django/forms/forms.py", line 284, in _clean_fields
    value = field.clean(value)
  File "/home/luka/etc/saion/ht_si/env/lib/python2.7/site-packages/django/forms/fields.py", line 163, in clean
    value = self.to_python(value)
  File "/home/luka/etc/saion/ht_si/env/lib/python2.7/site-packages/django/forms/models.py", line 972, in to_python
    value = self.queryset.get(**{key: value})
  File "/home/luka/etc/saion/ht_si/env/lib/python2.7/site-packages/django/db/models/query.py", line 341, in get
    clone = self.filter(*args, **kwargs)
  File "/home/luka/etc/saion/ht_si/env/lib/python2.7/site-packages/django/db/models/query.py", line 550, in filter
    return self._filter_or_exclude(False, *args, **kwargs)
  File "/home/luka/etc/saion/ht_si/env/lib/python2.7/site-packages/django/db/models/query.py", line 568, in _filter_or_exclude
    clone.query.add_q(Q(*args, **kwargs))
  File "/home/luka/etc/saion/ht_si/env/lib/python2.7/site-packages/django/db/models/sql/query.py", line 1194, in add_q
    can_reuse=used_aliases, force_having=force_having)
  File "/home/luka/etc/saion/ht_si/env/lib/python2.7/site-packages/django/db/models/sql/query.py", line 1129, in add_filter
    connector)
  File "/home/luka/etc/saion/ht_si/env/lib/python2.7/site-packages/django/db/models/sql/where.py", line 67, in add
    value = obj.prepare(lookup_type, value)
  File "/home/luka/etc/saion/ht_si/env/lib/python2.7/site-packages/django/db/models/sql/where.py", line 316, in prepare
    return self.field.get_prep_lookup(lookup_type, value)
  File "/home/luka/etc/saion/ht_si/env/lib/python2.7/site-packages/django/db/models/fields/__init__.py", line 292, in get_prep_lookup
    return self.get_prep_value(value)
  File "/home/luka/etc/saion/ht_si/env/lib/python2.7/site-packages/django/db/models/fields/__init__.py", line 479, in get_prep_value
    return int(value)
TypeError: int() argument must be a string or a number, not 'User'
2011-10-20 19:26:45,406 [WARNING] django.request: Not Found: /accounts/accounts.views.edit_player_profile
2011-10-20 19:27:20,613 [WARNING] django.request: Not Found: /accounts/edit_player_profile
2011-10-20 19:27:20,786 [ERROR] django.request: Internal Server Error: /accounts/edit_player_profile
Traceback (most recent call last):
  File "/home/luka/etc/saion/ht_si/env/lib/python2.7/site-packages/django/core/handlers/base.py", line 111, in get_response
    response = callback(request, *callback_args, **callback_kwargs)
  File "/home/luka/etc/saion/ht_si/env/lib/python2.7/site-packages/django/contrib/auth/decorators.py", line 23, in _wrapped_view
    return view_func(request, *args, **kwargs)
  File "/home/luka/etc/saion/ht_si/env/ht/accounts/views.py", line 68, in edit_player_profile
    user.save ( )
  File "/home/luka/etc/saion/ht_si/env/lib/python2.7/site-packages/django/db/models/base.py", line 460, in save
    self.save_base(using=using, force_insert=force_insert, force_update=force_update)
  File "/home/luka/etc/saion/ht_si/env/lib/python2.7/site-packages/django/db/models/base.py", line 526, in save_base
    rows = manager.using(using).filter(pk=pk_val)._update(values)
  File "/home/luka/etc/saion/ht_si/env/lib/python2.7/site-packages/django/db/models/query.py", line 491, in _update
    return query.get_compiler(self.db).execute_sql(None)
  File "/home/luka/etc/saion/ht_si/env/lib/python2.7/site-packages/django/db/models/sql/compiler.py", line 869, in execute_sql
    cursor = super(SQLUpdateCompiler, self).execute_sql(result_type)
  File "/home/luka/etc/saion/ht_si/env/lib/python2.7/site-packages/django/db/models/sql/compiler.py", line 735, in execute_sql
    cursor.execute(sql, params)
  File "/home/luka/etc/saion/ht_si/env/lib/python2.7/site-packages/django/db/backends/postgresql_psycopg2/base.py", line 44, in execute
    return self.cursor.execute(query, args)
DatabaseError: value too long for type character varying(30)

2011-10-20 19:27:21,275 [WARNING] django.request: Not Found: /accounts/accounts.views.edit_player_profile
2011-10-20 19:28:59,640 [WARNING] django.request: Not Found: /accounts/edit_player_profile
2011-10-20 19:29:00,331 [WARNING] django.request: Not Found: /accounts/accounts.views.edit_player_profile
2011-10-20 19:30:55,300 [WARNING] django.request: Not Found: /accounts/edit_player_profile
2011-10-20 19:30:55,463 [ERROR] django.request: Internal Server Error: /accounts/edit_player_profile
Traceback (most recent call last):
  File "/home/luka/etc/saion/ht_si/env/lib/python2.7/site-packages/django/core/handlers/base.py", line 111, in get_response
    response = callback(request, *callback_args, **callback_kwargs)
  File "/home/luka/etc/saion/ht_si/env/lib/python2.7/site-packages/django/contrib/auth/decorators.py", line 23, in _wrapped_view
    return view_func(request, *args, **kwargs)
  File "/home/luka/etc/saion/ht_si/env/ht/accounts/views.py", line 61, in edit_player_profile
    if form.is_valid ( ):
  File "/home/luka/etc/saion/ht_si/env/lib/python2.7/site-packages/django/forms/forms.py", line 121, in is_valid
    return self.is_bound and not bool(self.errors)
  File "/home/luka/etc/saion/ht_si/env/lib/python2.7/site-packages/django/forms/forms.py", line 112, in _get_errors
    self.full_clean()
  File "/home/luka/etc/saion/ht_si/env/lib/python2.7/site-packages/django/forms/forms.py", line 269, in full_clean
    self._post_clean()
  File "/home/luka/etc/saion/ht_si/env/lib/python2.7/site-packages/django/forms/models.py", line 308, in _post_clean
    self.instance = construct_instance(self, self.instance, opts.fields, opts.exclude)
  File "/home/luka/etc/saion/ht_si/env/lib/python2.7/site-packages/django/forms/models.py", line 50, in construct_instance
    f.save_form_data(instance, cleaned_data[f.name])
  File "/home/luka/etc/saion/ht_si/env/lib/python2.7/site-packages/django/db/models/fields/__init__.py", line 416, in save_form_data
    setattr(instance, self.name, data)
  File "/home/luka/etc/saion/ht_si/env/lib/python2.7/site-packages/django/db/models/fields/related.py", line 327, in __set__
    (instance._meta.object_name, self.field.name))
ValueError: Cannot assign None: "PlayerProfile.user" does not allow null values.
2011-10-20 19:30:55,970 [WARNING] django.request: Not Found: /accounts/accounts.views.edit_player_profile
2011-10-20 19:33:50,451 [WARNING] django.request: Not Found: /accounts/edit_player_profile
2011-10-20 19:33:50,611 [ERROR] django.request: Internal Server Error: /accounts/edit_player_profile
Traceback (most recent call last):
  File "/home/luka/etc/saion/ht_si/env/lib/python2.7/site-packages/django/core/handlers/base.py", line 111, in get_response
    response = callback(request, *callback_args, **callback_kwargs)
  File "/home/luka/etc/saion/ht_si/env/lib/python2.7/site-packages/django/contrib/auth/decorators.py", line 23, in _wrapped_view
    return view_func(request, *args, **kwargs)
  File "/home/luka/etc/saion/ht_si/env/ht/accounts/views.py", line 62, in edit_player_profile
    if form.is_valid ( ):
  File "/home/luka/etc/saion/ht_si/env/lib/python2.7/site-packages/django/forms/forms.py", line 121, in is_valid
    return self.is_bound and not bool(self.errors)
  File "/home/luka/etc/saion/ht_si/env/lib/python2.7/site-packages/django/forms/forms.py", line 112, in _get_errors
    self.full_clean()
  File "/home/luka/etc/saion/ht_si/env/lib/python2.7/site-packages/django/forms/forms.py", line 269, in full_clean
    self._post_clean()
  File "/home/luka/etc/saion/ht_si/env/lib/python2.7/site-packages/django/forms/models.py", line 308, in _post_clean
    self.instance = construct_instance(self, self.instance, opts.fields, opts.exclude)
  File "/home/luka/etc/saion/ht_si/env/lib/python2.7/site-packages/django/forms/models.py", line 50, in construct_instance
    f.save_form_data(instance, cleaned_data[f.name])
  File "/home/luka/etc/saion/ht_si/env/lib/python2.7/site-packages/django/db/models/fields/__init__.py", line 416, in save_form_data
    setattr(instance, self.name, data)
  File "/home/luka/etc/saion/ht_si/env/lib/python2.7/site-packages/django/db/models/fields/related.py", line 327, in __set__
    (instance._meta.object_name, self.field.name))
ValueError: Cannot assign None: "PlayerProfile.user" does not allow null values.
2011-10-20 19:33:51,099 [WARNING] django.request: Not Found: /accounts/accounts.views.edit_player_profile
2011-10-20 19:36:40,935 [WARNING] django.request: Not Found: /accounts/edit_player_profile
2011-10-20 19:36:41,094 [ERROR] django.request: Internal Server Error: /accounts/edit_player_profile
Traceback (most recent call last):
  File "/home/luka/etc/saion/ht_si/env/lib/python2.7/site-packages/django/core/handlers/base.py", line 111, in get_response
    response = callback(request, *callback_args, **callback_kwargs)
  File "/home/luka/etc/saion/ht_si/env/lib/python2.7/site-packages/django/contrib/auth/decorators.py", line 23, in _wrapped_view
    return view_func(request, *args, **kwargs)
  File "/home/luka/etc/saion/ht_si/env/ht/accounts/views.py", line 61, in edit_player_profile
    if form.is_valid ( ):
  File "/home/luka/etc/saion/ht_si/env/lib/python2.7/site-packages/django/forms/forms.py", line 121, in is_valid
    return self.is_bound and not bool(self.errors)
  File "/home/luka/etc/saion/ht_si/env/lib/python2.7/site-packages/django/forms/forms.py", line 112, in _get_errors
    self.full_clean()
  File "/home/luka/etc/saion/ht_si/env/lib/python2.7/site-packages/django/forms/forms.py", line 269, in full_clean
    self._post_clean()
  File "/home/luka/etc/saion/ht_si/env/lib/python2.7/site-packages/django/forms/models.py", line 308, in _post_clean
    self.instance = construct_instance(self, self.instance, opts.fields, opts.exclude)
  File "/home/luka/etc/saion/ht_si/env/lib/python2.7/site-packages/django/forms/models.py", line 50, in construct_instance
    f.save_form_data(instance, cleaned_data[f.name])
  File "/home/luka/etc/saion/ht_si/env/lib/python2.7/site-packages/django/db/models/fields/__init__.py", line 416, in save_form_data
    setattr(instance, self.name, data)
  File "/home/luka/etc/saion/ht_si/env/lib/python2.7/site-packages/django/db/models/fields/related.py", line 327, in __set__
    (instance._meta.object_name, self.field.name))
ValueError: Cannot assign None: "PlayerProfile.user" does not allow null values.
2011-10-20 19:36:41,583 [WARNING] django.request: Not Found: /accounts/accounts.views.edit_player_profile
2011-10-20 19:37:18,536 [WARNING] django.request: Not Found: /accounts/edit_player_profile
2011-10-20 19:38:00,265 [ERROR] django.request: Internal Server Error: /accounts/edit_player_profile
Traceback (most recent call last):
  File "/home/luka/etc/saion/ht_si/env/lib/python2.7/site-packages/django/core/handlers/base.py", line 111, in get_response
    response = callback(request, *callback_args, **callback_kwargs)
  File "/home/luka/etc/saion/ht_si/env/lib/python2.7/site-packages/django/contrib/auth/decorators.py", line 23, in _wrapped_view
    return view_func(request, *args, **kwargs)
  File "/home/luka/etc/saion/ht_si/env/ht/accounts/views.py", line 62, in edit_player_profile
    if form.is_valid ( ):
  File "/home/luka/etc/saion/ht_si/env/lib/python2.7/site-packages/django/forms/forms.py", line 121, in is_valid
    return self.is_bound and not bool(self.errors)
  File "/home/luka/etc/saion/ht_si/env/lib/python2.7/site-packages/django/forms/forms.py", line 112, in _get_errors
    self.full_clean()
  File "/home/luka/etc/saion/ht_si/env/lib/python2.7/site-packages/django/forms/forms.py", line 269, in full_clean
    self._post_clean()
  File "/home/luka/etc/saion/ht_si/env/lib/python2.7/site-packages/django/forms/models.py", line 308, in _post_clean
    self.instance = construct_instance(self, self.instance, opts.fields, opts.exclude)
  File "/home/luka/etc/saion/ht_si/env/lib/python2.7/site-packages/django/forms/models.py", line 50, in construct_instance
    f.save_form_data(instance, cleaned_data[f.name])
  File "/home/luka/etc/saion/ht_si/env/lib/python2.7/site-packages/django/db/models/fields/__init__.py", line 416, in save_form_data
    setattr(instance, self.name, data)
  File "/home/luka/etc/saion/ht_si/env/lib/python2.7/site-packages/django/db/models/fields/related.py", line 327, in __set__
    (instance._meta.object_name, self.field.name))
ValueError: Cannot assign None: "PlayerProfile.user" does not allow null values.
2011-10-20 19:38:00,757 [WARNING] django.request: Not Found: /accounts/accounts.views.edit_player_profile
2011-10-20 19:41:31,410 [WARNING] django.request: Not Found: /accounts/edit_player_profile
2011-10-20 19:41:34,065 [ERROR] django.request: Internal Server Error: /accounts/edit_player_profile
Traceback (most recent call last):
  File "/home/luka/etc/saion/ht_si/env/lib/python2.7/site-packages/django/core/handlers/base.py", line 111, in get_response
    response = callback(request, *callback_args, **callback_kwargs)
  File "/home/luka/etc/saion/ht_si/env/lib/python2.7/site-packages/django/contrib/auth/decorators.py", line 23, in _wrapped_view
    return view_func(request, *args, **kwargs)
  File "/home/luka/etc/saion/ht_si/env/ht/accounts/views.py", line 63, in edit_player_profile
    if form.is_valid ( ):
  File "/home/luka/etc/saion/ht_si/env/lib/python2.7/site-packages/django/db/models/base.py", line 460, in save
    self.save_base(using=using, force_insert=force_insert, force_update=force_update)
  File "/home/luka/etc/saion/ht_si/env/lib/python2.7/site-packages/django/db/models/base.py", line 526, in save_base
    rows = manager.using(using).filter(pk=pk_val)._update(values)
  File "/home/luka/etc/saion/ht_si/env/lib/python2.7/site-packages/django/db/models/query.py", line 491, in _update
    return query.get_compiler(self.db).execute_sql(None)
  File "/home/luka/etc/saion/ht_si/env/lib/python2.7/site-packages/django/db/models/sql/compiler.py", line 869, in execute_sql
    cursor = super(SQLUpdateCompiler, self).execute_sql(result_type)
  File "/home/luka/etc/saion/ht_si/env/lib/python2.7/site-packages/django/db/models/sql/compiler.py", line 735, in execute_sql
    cursor.execute(sql, params)
  File "/home/luka/etc/saion/ht_si/env/lib/python2.7/site-packages/django/db/backends/postgresql_psycopg2/base.py", line 44, in execute
    return self.cursor.execute(query, args)
DatabaseError: value too long for type character varying(30)

2011-10-20 19:41:34,553 [WARNING] django.request: Not Found: /accounts/accounts.views.edit_player_profile
2011-10-20 19:43:07,999 [WARNING] django.request: Not Found: /accounts/edit_player_profile
2011-10-20 19:43:09,552 [WARNING] django.request: Not Found: /accounts/accounts.views.edit_player_profile
2011-10-20 19:44:23,577 [WARNING] django.request: Not Found: /accounts/edit_player_profile
2011-10-20 19:44:24,239 [WARNING] django.request: Not Found: /accounts/accounts.views.edit_player_profile
2011-10-20 19:57:35,108 [WARNING] django.request: Not Found: /accounts/edit_player_profile
2011-10-20 19:57:35,842 [WARNING] django.request: Not Found: /accounts/accounts.views.edit_player_profile
2011-10-20 19:58:47,898 [WARNING] django.request: Not Found: /accounts/edit_player_profile
2011-10-20 19:59:48,404 [WARNING] django.request: Not Found: /accounts/accounts.views.edit_player_profile
2011-10-20 20:01:27,403 [WARNING] django.request: Not Found: /accounts/edit_player_profile
2011-10-20 20:01:28,109 [WARNING] django.request: Not Found: /accounts/accounts.views.edit_player_profile
2011-10-20 20:08:02,964 [WARNING] django.request: Not Found: /accounts/edit_player_profile
2011-10-20 20:08:03,667 [WARNING] django.request: Not Found: /accounts/accounts.views.edit_player_profile
2011-10-20 20:11:00,752 [WARNING] django.request: Not Found: /accounts/edit_player_profile
2011-10-20 20:11:01,451 [WARNING] django.request: Not Found: /accounts/accounts.views.edit_player_profile
2011-10-20 20:15:24,371 [WARNING] django.request: Not Found: /accounts/edit_player_profile
2011-10-20 20:15:25,075 [WARNING] django.request: Not Found: /accounts/accounts.views.edit_player_profile
2011-10-20 20:18:43,016 [WARNING] django.request: Not Found: /accounts/edit_player_profile
2011-10-20 20:18:43,682 [WARNING] django.request: Not Found: /accounts/accounts.views.edit_player_profile
2011-10-20 20:19:44,118 [WARNING] django.request: Not Found: /accounts/edit_player_profile
2011-10-20 20:19:44,817 [WARNING] django.request: Not Found: /accounts/accounts.views.edit_player_profile
2011-10-20 20:20:09,298 [WARNING] django.request: Not Found: /accounts/edit_player_profile
2011-10-20 20:20:09,962 [WARNING] django.request: Not Found: /accounts/accounts.views.edit_player_profile
2011-10-20 20:42:57,705 [WARNING] django.request: Not Found: /accounts/img/personal_information.png
2011-10-20 20:42:57,807 [WARNING] django.request: Not Found: /accounts/img/personal_information.png
2011-10-20 20:45:02,020 [WARNING] django.request: Not Found: /accounts/img/personal_information.png
2011-10-20 20:45:02,127 [WARNING] django.request: Not Found: /accounts/img/personal_information.png
2011-10-20 20:46:51,394 [WARNING] django.request: Not Found: /accounts/img/personal_information.png
2011-10-20 20:46:51,498 [WARNING] django.request: Not Found: /accounts/img/personal_information.png
2011-10-20 20:46:52,185 [WARNING] django.request: Not Found: /accounts/img/personal_information.png
2011-10-20 20:46:52,288 [WARNING] django.request: Not Found: /accounts/img/personal_information.png
2011-10-20 20:48:27,706 [WARNING] django.request: Not Found: /accounts/img/personal_information.png
2011-10-20 20:48:27,807 [WARNING] django.request: Not Found: /accounts/img/personal_information.png
2011-10-20 20:49:01,839 [WARNING] django.request: Not Found: /accounts/img/personal_information.png
2011-10-20 20:49:01,930 [WARNING] django.request: Not Found: /accounts/img/personal_information.png
2011-10-20 20:49:03,362 [WARNING] django.request: Not Found: /accounts/img/personal_information.png
2011-10-20 20:49:03,479 [WARNING] django.request: Not Found: /accounts/img/personal_information.png
2011-10-20 20:49:30,853 [WARNING] django.request: Not Found: /accounts/img/personal_information.png
2011-10-20 20:49:30,962 [WARNING] django.request: Not Found: /accounts/img/personal_information.png
2011-10-20 20:49:31,683 [WARNING] django.request: Not Found: /accounts/img/personal_information.png
2011-10-20 20:49:31,784 [WARNING] django.request: Not Found: /accounts/img/personal_information.png
2011-10-20 20:49:58,668 [WARNING] django.request: Not Found: /accounts/img/personal_information.png
2011-10-20 20:49:58,762 [WARNING] django.request: Not Found: /accounts/img/personal_information.png
2011-10-20 20:49:59,573 [WARNING] django.request: Not Found: /accounts/img/personal_information.png
2011-10-20 20:49:59,668 [WARNING] django.request: Not Found: /accounts/img/personal_information.png
2011-10-20 20:50:05,709 [WARNING] django.request: Not Found: /accounts/img/personal_information.png
2011-10-20 20:50:05,813 [WARNING] django.request: Not Found: /accounts/img/personal_information.png
2011-10-20 20:50:06,448 [WARNING] django.request: Not Found: /accounts/img/personal_information.png
2011-10-20 20:50:06,549 [WARNING] django.request: Not Found: /accounts/img/personal_information.png
2011-10-20 20:50:11,761 [WARNING] django.request: Not Found: /accounts/img/personal_information.png
2011-10-20 20:50:11,863 [WARNING] django.request: Not Found: /accounts/img/personal_information.png
2011-10-20 20:50:12,373 [WARNING] django.request: Not Found: /accounts/img/personal_information.png
2011-10-20 20:50:12,485 [WARNING] django.request: Not Found: /accounts/img/personal_information.png
2011-10-20 20:50:13,127 [WARNING] django.request: Not Found: /accounts/img/personal_information.png
2011-10-20 20:50:13,230 [WARNING] django.request: Not Found: /accounts/img/personal_information.png
2011-10-20 20:50:39,528 [WARNING] django.request: Not Found: /accounts/img/personal_information.png
2011-10-20 20:50:39,623 [WARNING] django.request: Not Found: /accounts/img/personal_information.png
2011-10-20 20:50:51,796 [WARNING] django.request: Not Found: /accounts/img/personal_information.png
2011-10-20 20:50:51,891 [WARNING] django.request: Not Found: /accounts/img/personal_information.png
2011-10-20 20:51:23,511 [WARNING] django.request: Not Found: /accounts/img/personal_information.png
2011-10-20 20:51:23,612 [WARNING] django.request: Not Found: /accounts/img/personal_information.png
2011-10-20 20:51:24,147 [WARNING] django.request: Not Found: /accounts/img/personal_information.png
2011-10-20 20:51:24,242 [WARNING] django.request: Not Found: /accounts/img/personal_information.png
2011-10-20 20:51:32,043 [WARNING] django.request: Not Found: /accounts/img/personal_information.png
2011-10-20 20:51:32,136 [WARNING] django.request: Not Found: /accounts/img/personal_information.png
2011-10-20 20:51:32,866 [WARNING] django.request: Not Found: /accounts/img/personal_information.png
2011-10-20 20:51:32,962 [WARNING] django.request: Not Found: /accounts/img/personal_information.png
2011-10-20 20:51:47,378 [WARNING] django.request: Not Found: /accounts/img/personal_information.png
2011-10-20 20:51:47,473 [WARNING] django.request: Not Found: /accounts/img/personal_information.png
2011-10-20 20:52:11,577 [WARNING] django.request: Not Found: /accounts/img/personal_information.png
2011-10-20 20:52:11,685 [WARNING] django.request: Not Found: /accounts/img/personal_information.png
2011-10-20 20:52:32,860 [WARNING] django.request: Not Found: /accounts/img/personal_information.png
2011-10-20 20:52:32,956 [WARNING] django.request: Not Found: /accounts/img/personal_information.png
2011-10-20 20:52:40,981 [WARNING] django.request: Not Found: /accounts/img/personal_information.png
2011-10-20 20:52:41,082 [WARNING] django.request: Not Found: /accounts/img/personal_information.png
2011-10-20 20:52:54,245 [WARNING] django.request: Not Found: /accounts/img/personal_information.png
2011-10-20 20:52:54,345 [WARNING] django.request: Not Found: /accounts/img/personal_information.png
2011-10-20 20:53:08,553 [WARNING] django.request: Not Found: /accounts/img/personal_information.png
2011-10-20 20:53:08,656 [WARNING] django.request: Not Found: /accounts/img/personal_information.png
2011-10-20 21:20:00,003 [WARNING] django.request: Not Found: /accounts/img/availability.png
2011-10-20 21:20:00,126 [WARNING] django.request: Not Found: /accounts/img/availability.png
2011-10-20 21:20:14,992 [WARNING] django.request: Not Found: /accounts/img/availability.png
2011-10-20 21:20:15,082 [WARNING] django.request: Not Found: /accounts/img/availability.png
2011-10-20 21:21:06,351 [WARNING] django.request: Not Found: /accounts/img/availability.png
2011-10-20 21:21:06,457 [WARNING] django.request: Not Found: /accounts/img/availability.png
2011-10-20 21:21:39,020 [WARNING] django.request: Not Found: /accounts/img/availability.png
2011-10-20 21:21:39,112 [WARNING] django.request: Not Found: /accounts/img/availability.png
2011-10-24 11:06:51,991 [WARNING] django.request: Not Found: /favicon.ico
2011-10-24 11:06:55,959 [WARNING] django.request: Not Found: /favicon.ico
2011-10-24 11:07:00,985 [WARNING] django.request: Not Found: /favicon.ico
2011-10-24 11:07:02,971 [WARNING] django.request: Not Found: /favicon.ico
2011-10-24 11:07:05,077 [WARNING] django.request: Not Found: /favicon.ico
2011-10-24 11:07:10,244 [WARNING] django.request: Not Found: /reservations/price_1321
2011-10-24 11:07:10,330 [WARNING] django.request: Not Found: /favicon.ico
2011-10-24 11:07:18,574 [WARNING] django.request: Not Found: /favicon.ico
2011-10-24 11:07:21,194 [WARNING] django.request: Not Found: /reservations/price_1322
2011-10-24 11:07:21,242 [WARNING] django.request: Not Found: /favicon.ico
2011-10-24 11:07:22,722 [WARNING] django.request: Not Found: /favicon.ico
2011-10-24 11:49:15,848 [WARNING] django.request: Not Found: /favicon.ico
2011-10-24 11:50:06,032 [WARNING] django.request: Not Found: /favicon.ico
2011-10-24 12:36:23,129 [ERROR] django.request: Internal Server Error: /user_messages/feedback/
Traceback (most recent call last):
  File "/home/luka/etc/saion/ht_si/env/lib/python2.7/site-packages/django/core/handlers/base.py", line 111, in get_response
    response = callback(request, *callback_args, **callback_kwargs)
  File "/home/luka/etc/saion/ht_si/env/ht/user_messages/views.py", line 39, in feedback
    message_list = Message.objects.inbox_for(request.user)
  File "/home/luka/etc/saion/ht_si/env/ht/user_messages/models.py", line 17, in inbox_for
    recipient_deleted_at__isnull=True,
  File "/home/luka/etc/saion/ht_si/env/lib/python2.7/site-packages/django/db/models/manager.py", line 141, in filter
    return self.get_query_set().filter(*args, **kwargs)
  File "/home/luka/etc/saion/ht_si/env/lib/python2.7/site-packages/django/db/models/query.py", line 550, in filter
    return self._filter_or_exclude(False, *args, **kwargs)
  File "/home/luka/etc/saion/ht_si/env/lib/python2.7/site-packages/django/db/models/query.py", line 568, in _filter_or_exclude
    clone.query.add_q(Q(*args, **kwargs))
  File "/home/luka/etc/saion/ht_si/env/lib/python2.7/site-packages/django/db/models/sql/query.py", line 1194, in add_q
    can_reuse=used_aliases, force_having=force_having)
  File "/home/luka/etc/saion/ht_si/env/lib/python2.7/site-packages/django/db/models/sql/query.py", line 1129, in add_filter
    connector)
  File "/home/luka/etc/saion/ht_si/env/lib/python2.7/site-packages/django/db/models/sql/where.py", line 67, in add
    value = obj.prepare(lookup_type, value)
  File "/home/luka/etc/saion/ht_si/env/lib/python2.7/site-packages/django/db/models/sql/where.py", line 316, in prepare
    return self.field.get_prep_lookup(lookup_type, value)
  File "/home/luka/etc/saion/ht_si/env/lib/python2.7/site-packages/django/db/models/fields/related.py", line 136, in get_prep_lookup
    return self._pk_trace(value, 'get_prep_lookup', lookup_type)
  File "/home/luka/etc/saion/ht_si/env/lib/python2.7/site-packages/django/db/models/fields/related.py", line 209, in _pk_trace
    v = getattr(field, prep_func)(lookup_type, v, **kwargs)
  File "/home/luka/etc/saion/ht_si/env/lib/python2.7/site-packages/django/db/models/fields/__init__.py", line 292, in get_prep_lookup
    return self.get_prep_value(value)
  File "/home/luka/etc/saion/ht_si/env/lib/python2.7/site-packages/django/db/models/fields/__init__.py", line 479, in get_prep_value
    return int(value)
TypeError: int() argument must be a string or a number, not 'AnonymousUser'
2011-10-24 12:40:37,345 [ERROR] django.request: Internal Server Error: /user_messages/feedback/
Traceback (most recent call last):
  File "/home/luka/etc/saion/ht_si/env/lib/python2.7/site-packages/django/core/handlers/base.py", line 111, in get_response
    response = callback(request, *callback_args, **callback_kwargs)
  File "/home/luka/etc/saion/ht_si/env/ht/user_messages/views.py", line 39, in feedback
    message_list = Message.objects.inbox_for(request.user)
  File "/home/luka/etc/saion/ht_si/env/ht/user_messages/models.py", line 17, in inbox_for
    recipient_deleted_at__isnull=True,
  File "/home/luka/etc/saion/ht_si/env/lib/python2.7/site-packages/django/db/models/manager.py", line 141, in filter
    return self.get_query_set().filter(*args, **kwargs)
  File "/home/luka/etc/saion/ht_si/env/lib/python2.7/site-packages/django/db/models/query.py", line 550, in filter
    return self._filter_or_exclude(False, *args, **kwargs)
  File "/home/luka/etc/saion/ht_si/env/lib/python2.7/site-packages/django/db/models/query.py", line 568, in _filter_or_exclude
    clone.query.add_q(Q(*args, **kwargs))
  File "/home/luka/etc/saion/ht_si/env/lib/python2.7/site-packages/django/db/models/sql/query.py", line 1194, in add_q
    can_reuse=used_aliases, force_having=force_having)
  File "/home/luka/etc/saion/ht_si/env/lib/python2.7/site-packages/django/db/models/sql/query.py", line 1129, in add_filter
    connector)
  File "/home/luka/etc/saion/ht_si/env/lib/python2.7/site-packages/django/db/models/sql/where.py", line 67, in add
    value = obj.prepare(lookup_type, value)
  File "/home/luka/etc/saion/ht_si/env/lib/python2.7/site-packages/django/db/models/sql/where.py", line 316, in prepare
    return self.field.get_prep_lookup(lookup_type, value)
  File "/home/luka/etc/saion/ht_si/env/lib/python2.7/site-packages/django/db/models/fields/related.py", line 136, in get_prep_lookup
    return self._pk_trace(value, 'get_prep_lookup', lookup_type)
  File "/home/luka/etc/saion/ht_si/env/lib/python2.7/site-packages/django/db/models/fields/related.py", line 209, in _pk_trace
    v = getattr(field, prep_func)(lookup_type, v, **kwargs)
  File "/home/luka/etc/saion/ht_si/env/lib/python2.7/site-packages/django/db/models/fields/__init__.py", line 292, in get_prep_lookup
    return self.get_prep_value(value)
  File "/home/luka/etc/saion/ht_si/env/lib/python2.7/site-packages/django/db/models/fields/__init__.py", line 479, in get_prep_value
    return int(value)
TypeError: int() argument must be a string or a number, not 'AnonymousUser'
2011-10-24 13:02:24,480 [ERROR] django.request: Internal Server Error: /user_messages/feedback/
Traceback (most recent call last):
  File "/home/luka/etc/saion/ht_si/env/lib/python2.7/site-packages/django/core/handlers/base.py", line 111, in get_response
    response = callback(request, *callback_args, **callback_kwargs)
  File "/home/luka/etc/saion/ht_si/env/lib/python2.7/site-packages/django/contrib/auth/decorators.py", line 23, in _wrapped_view
    return view_func(request, *args, **kwargs)
  File "/home/luka/etc/saion/ht_si/env/ht/user_messages/views.py", line 42, in feedback
    template_name=template_name)
  File "/home/luka/etc/saion/ht_si/env/lib/python2.7/site-packages/django/contrib/auth/decorators.py", line 23, in _wrapped_view
    return view_func(request, *args, **kwargs)
  File "/home/luka/etc/saion/ht_si/env/ht/user_messages/views.py", line 118, in compose
    recipients = [u for u in User.objects.filter(username__in=[r.strip() for r in recipient.split('+')])]
AttributeError: 'User' object has no attribute 'split'
2011-10-24 13:12:38,810 [ERROR] django.request: Internal Server Error: /user_messages/compose/
Traceback (most recent call last):
  File "/home/luka/etc/saion/ht_si/env/lib/python2.7/site-packages/django/core/handlers/base.py", line 111, in get_response
    response = callback(request, *callback_args, **callback_kwargs)
  File "/home/luka/etc/saion/ht_si/env/lib/python2.7/site-packages/django/contrib/auth/decorators.py", line 23, in _wrapped_view
    return view_func(request, *args, **kwargs)
  File "/home/luka/etc/saion/ht_si/env/ht/user_messages/views.py", line 117, in compose
    form.fields['sender'].initial = sender
NameError: global name 'sender' is not defined
2011-10-24 13:22:00,457 [ERROR] django.request: Internal Server Error: /user_messages/feedback/
Traceback (most recent call last):
  File "/home/luka/etc/saion/ht_si/env/lib/python2.7/site-packages/django/core/handlers/base.py", line 111, in get_response
    response = callback(request, *callback_args, **callback_kwargs)
  File "/home/luka/etc/saion/ht_si/env/lib/python2.7/site-packages/django/contrib/auth/decorators.py", line 23, in _wrapped_view
    return view_func(request, *args, **kwargs)
  File "/home/luka/etc/saion/ht_si/env/ht/user_messages/views.py", line 34, in feedback
    subject = '%s %s' % ('Feedback', request['PATH_INFO'])
TypeError: 'WSGIRequest' object is not subscriptable
2011-10-24 14:41:04,653 [ERROR] django.request: Internal Server Error: /user_messages/feedback/
Traceback (most recent call last):
  File "/home/luka/etc/saion/ht_si/env/lib/python2.7/site-packages/django/core/handlers/base.py", line 111, in get_response
    response = callback(request, *callback_args, **callback_kwargs)
  File "/home/luka/etc/saion/ht_si/env/lib/python2.7/site-packages/django/contrib/auth/decorators.py", line 23, in _wrapped_view
    return view_func(request, *args, **kwargs)
  File "/home/luka/etc/saion/ht_si/env/ht/user_messages/views.py", line 35, in feedback
    params['success_url'] = request.META['HTTP_REFERER']
TypeError: 'WSGIRequest' object is not subscriptable
2011-10-24 14:41:43,842 [ERROR] django.request: Internal Server Error: /user_messages/feedback/
Traceback (most recent call last):
  File "/home/luka/etc/saion/ht_si/env/lib/python2.7/site-packages/django/core/handlers/base.py", line 111, in get_response
    response = callback(request, *callback_args, **callback_kwargs)
  File "/home/luka/etc/saion/ht_si/env/lib/python2.7/site-packages/django/contrib/auth/decorators.py", line 23, in _wrapped_view
    return view_func(request, *args, **kwargs)
  File "/home/luka/etc/saion/ht_si/env/ht/user_messages/views.py", line 39, in feedback
    return compose (**params)
TypeError: _wrapped_view() takes at least 1 argument (0 given)
2011-10-24 15:09:28,541 [WARNING] django.request: Not Found: /user_messages/feedback/
2011-10-24 15:25:41,869 [ERROR] django.request: Internal Server Error: /user_messages/compose/
Traceback (most recent call last):
  File "/home/luka/etc/saion/ht_si/env/lib/python2.7/site-packages/django/core/handlers/base.py", line 111, in get_response
    response = callback(request, *callback_args, **callback_kwargs)
  File "/home/luka/etc/saion/ht_si/env/lib/python2.7/site-packages/django/contrib/auth/decorators.py", line 23, in _wrapped_view
    return view_func(request, *args, **kwargs)
  File "/home/luka/etc/saion/ht_si/env/ht/user_messages/views.py", line 131, in compose
    'success_url': urlparse(success_url).path},
  File "/usr/lib/python2.7/urlparse.py", line 134, in urlparse
    tuple = urlsplit(url, scheme, allow_fragments)
  File "/usr/lib/python2.7/urlparse.py", line 173, in urlsplit
    i = url.find(':')
AttributeError: 'NoneType' object has no attribute 'find'
2011-10-24 15:28:56,247 [ERROR] django.request: Internal Server Error: /user_messages/compose/
Traceback (most recent call last):
  File "/home/luka/etc/saion/ht_si/env/lib/python2.7/site-packages/django/core/handlers/base.py", line 111, in get_response
    response = callback(request, *callback_args, **callback_kwargs)
  File "/home/luka/etc/saion/ht_si/env/lib/python2.7/site-packages/django/contrib/auth/decorators.py", line 23, in _wrapped_view
    return view_func(request, *args, **kwargs)
  File "/home/luka/etc/saion/ht_si/env/ht/user_messages/views.py", line 131, in compose
    'success_url': urlparse(success_url).path},
  File "/usr/lib/python2.7/urlparse.py", line 134, in urlparse
    tuple = urlsplit(url, scheme, allow_fragments)
  File "/usr/lib/python2.7/urlparse.py", line 173, in urlsplit
    i = url.find(':')
AttributeError: 'NoneType' object has no attribute 'find'
2011-10-24 15:33:58,981 [ERROR] django.request: Internal Server Error: /user_messages/compose/
Traceback (most recent call last):
  File "/home/luka/etc/saion/ht_si/env/lib/python2.7/site-packages/django/core/handlers/base.py", line 111, in get_response
    response = callback(request, *callback_args, **callback_kwargs)
  File "/home/luka/etc/saion/ht_si/env/lib/python2.7/site-packages/django/contrib/auth/decorators.py", line 23, in _wrapped_view
    return view_func(request, *args, **kwargs)
  File "/home/luka/etc/saion/ht_si/env/ht/user_messages/views.py", line 131, in compose
    'success_url': urlparse(success_url).path},
  File "/usr/lib/python2.7/urlparse.py", line 134, in urlparse
    tuple = urlsplit(url, scheme, allow_fragments)
  File "/usr/lib/python2.7/urlparse.py", line 173, in urlsplit
    i = url.find(':')
AttributeError: 'NoneType' object has no attribute 'find'
2011-10-24 15:36:25,437 [ERROR] django.request: Internal Server Error: /user_messages/compose/
Traceback (most recent call last):
  File "/home/luka/etc/saion/ht_si/env/lib/python2.7/site-packages/django/core/handlers/base.py", line 111, in get_response
    response = callback(request, *callback_args, **callback_kwargs)
  File "/home/luka/etc/saion/ht_si/env/lib/python2.7/site-packages/django/contrib/auth/decorators.py", line 23, in _wrapped_view
    return view_func(request, *args, **kwargs)
  File "/home/luka/etc/saion/ht_si/env/ht/user_messages/views.py", line 131, in compose
    'success_url': urlparse(success_url).path},
  File "/usr/lib/python2.7/urlparse.py", line 134, in urlparse
    tuple = urlsplit(url, scheme, allow_fragments)
  File "/usr/lib/python2.7/urlparse.py", line 173, in urlsplit
    i = url.find(':')
AttributeError: 'NoneType' object has no attribute 'find'
2011-10-24 15:36:48,939 [ERROR] django.request: Internal Server Error: /user_messages/compose/
Traceback (most recent call last):
  File "/home/luka/etc/saion/ht_si/env/lib/python2.7/site-packages/django/core/handlers/base.py", line 111, in get_response
    response = callback(request, *callback_args, **callback_kwargs)
  File "/home/luka/etc/saion/ht_si/env/lib/python2.7/site-packages/django/contrib/auth/decorators.py", line 23, in _wrapped_view
    return view_func(request, *args, **kwargs)
  File "/home/luka/etc/saion/ht_si/env/ht/user_messages/views.py", line 131, in compose
    'success_url': urlparse(success_url).path},
  File "/usr/lib/python2.7/urlparse.py", line 134, in urlparse
    tuple = urlsplit(url, scheme, allow_fragments)
  File "/usr/lib/python2.7/urlparse.py", line 173, in urlsplit
    i = url.find(':')
AttributeError: 'NoneType' object has no attribute 'find'
2011-10-24 16:01:07,776 [ERROR] django.request: Internal Server Error: /user_messages/compose/
Traceback (most recent call last):
  File "/home/luka/etc/saion/ht_si/env/lib/python2.7/site-packages/django/core/handlers/base.py", line 111, in get_response
    response = callback(request, *callback_args, **callback_kwargs)
  File "/home/luka/etc/saion/ht_si/env/lib/python2.7/site-packages/django/contrib/auth/decorators.py", line 23, in _wrapped_view
    return view_func(request, *args, **kwargs)
  File "/home/luka/etc/saion/ht_si/env/ht/user_messages/views.py", line 131, in compose
    'success_url': urlparse(success_url).path},
  File "/usr/lib/python2.7/urlparse.py", line 134, in urlparse
    tuple = urlsplit(url, scheme, allow_fragments)
  File "/usr/lib/python2.7/urlparse.py", line 173, in urlsplit
    i = url.find(':')
AttributeError: 'NoneType' object has no attribute 'find'
2011-10-24 16:01:48,710 [ERROR] django.request: Internal Server Error: /user_messages/compose/
Traceback (most recent call last):
  File "/home/luka/etc/saion/ht_si/env/lib/python2.7/site-packages/django/core/handlers/base.py", line 111, in get_response
    response = callback(request, *callback_args, **callback_kwargs)
  File "/home/luka/etc/saion/ht_si/env/lib/python2.7/site-packages/django/contrib/auth/decorators.py", line 23, in _wrapped_view
    return view_func(request, *args, **kwargs)
  File "/home/luka/etc/saion/ht_si/env/ht/user_messages/views.py", line 131, in compose
    'success_url': urlparse(success_url).path},
  File "/usr/lib/python2.7/urlparse.py", line 134, in urlparse
    tuple = urlsplit(url, scheme, allow_fragments)
  File "/usr/lib/python2.7/urlparse.py", line 173, in urlsplit
    i = url.find(':')
AttributeError: 'NoneType' object has no attribute 'find'
2011-10-24 16:08:42,587 [WARNING] django.request: Not Found: /accounts/edit_player_profile
2011-10-24 16:08:43,400 [WARNING] django.request: Not Found: /accounts/accounts.views.edit_player_profile
2011-10-24 16:17:22,080 [WARNING] django.request: Not Found: /accounts/edit_player_profile
2011-10-24 16:17:23,177 [WARNING] django.request: Not Found: /accounts/accounts.views.edit_player_profile
2011-10-24 19:16:49,155 [WARNING] django.request: Not Found: /reservations/make_reservation
2011-10-24 19:16:49,195 [WARNING] django.request: Not Found: /favicon.ico
2011-10-24 19:16:49,204 [WARNING] django.request: Not Found: /favicon.ico
2011-10-25 11:02:00,283 [WARNING] django.request: Not Found: /favicon.ico
2011-10-25 11:02:01,931 [WARNING] django.request: Not Found: /favicon.ico
2011-10-25 11:02:14,521 [WARNING] django.request: Not Found: /favicon.ico
2011-10-25 11:02:16,994 [WARNING] django.request: Not Found: /favicon.ico
2011-10-25 11:02:18,594 [WARNING] django.request: Not Found: /favicon.ico
2011-10-25 11:02:19,788 [WARNING] django.request: Not Found: /favicon.ico
2011-10-25 11:02:21,480 [WARNING] django.request: Not Found: /favicon.ico
2011-10-25 11:12:28,859 [WARNING] django.request: Not Found: /favicon.ico
2011-10-25 11:12:30,866 [WARNING] django.request: Not Found: /favicon.ico
2011-10-25 11:12:32,905 [WARNING] django.request: Not Found: /favicon.ico
2011-10-25 11:12:35,613 [WARNING] django.request: Not Found: /favicon.ico
2011-10-25 11:12:39,001 [WARNING] django.request: Not Found: /favicon.ico
2011-10-25 11:12:59,424 [WARNING] django.request: Not Found: /favicon.ico
2011-10-25 11:13:01,403 [WARNING] django.request: Not Found: /favicon.ico
2011-10-25 11:13:03,170 [WARNING] django.request: Not Found: /favicon.ico
2011-10-25 11:13:04,830 [WARNING] django.request: Not Found: /favicon.ico
2011-10-25 11:13:05,938 [WARNING] django.request: Not Found: /favicon.ico
2011-10-25 11:13:08,092 [WARNING] django.request: Not Found: /favicon.ico
2011-10-25 11:13:12,634 [WARNING] django.request: Not Found: /favicon.ico
2011-10-25 11:13:16,948 [WARNING] django.request: Not Found: /favicon.ico
2011-10-25 11:13:25,641 [WARNING] django.request: Not Found: /favicon.ico
2011-10-25 11:13:28,745 [WARNING] django.request: Not Found: /favicon.ico
2011-10-25 11:13:30,078 [WARNING] django.request: Not Found: /favicon.ico
2011-10-25 11:13:32,816 [WARNING] django.request: Not Found: /favicon.ico
2011-10-25 11:13:35,119 [WARNING] django.request: Not Found: /favicon.ico
2011-10-25 11:13:41,470 [WARNING] django.request: Not Found: /favicon.ico
2011-10-25 11:13:56,467 [WARNING] django.request: Not Found: /favicon.ico
2011-10-25 11:13:59,979 [WARNING] django.request: Not Found: /favicon.ico
2011-10-25 11:14:01,964 [WARNING] django.request: Not Found: /favicon.ico
2011-10-25 11:14:10,025 [WARNING] django.request: Not Found: /favicon.ico
2011-10-25 11:39:56,414 [WARNING] django.request: Not Found: /accounts/edit_player_profile
2011-10-25 11:39:57,103 [WARNING] django.request: Not Found: /accounts/accounts.views.edit_player_profile
2011-10-25 11:43:12,962 [WARNING] django.request: Not Found: /reservations/user_view
2011-10-25 12:01:58,029 [ERROR] django.request: Internal Server Error: /reservations/search
Traceback (most recent call last):
  File "/home/luka/etc/saion/ht_si/env/lib/python2.7/site-packages/django/core/handlers/base.py", line 111, in get_response
    response = callback(request, *callback_args, **callback_kwargs)
  File "/home/luka/etc/saion/ht_si/env/ht/reservations/views.py", line 269, in search
    {'form': form,},
UnboundLocalError: local variable 'form' referenced before assignment
2011-10-25 12:27:53,294 [ERROR] django.request: Internal Server Error: /reservations/user_view
Traceback (most recent call last):
  File "/home/luka/etc/saion/ht_si/env/lib/python2.7/site-packages/django/core/handlers/base.py", line 129, in get_response
    raise ValueError("The view %s.%s didn't return an HttpResponse object." % (callback.__module__, view_name))
ValueError: The view reservations.views.user_view didn't return an HttpResponse object.
2011-10-25 12:32:42,030 [ERROR] django.request: Internal Server Error: /reservations/search
Traceback (most recent call last):
  File "/home/luka/etc/saion/ht_si/env/lib/python2.7/site-packages/django/core/handlers/base.py", line 111, in get_response
    response = callback(request, *callback_args, **callback_kwargs)
  File "/home/luka/etc/saion/ht_si/env/ht/reservations/views.py", line 251, in search
    context_instance=RequestContext(request))
  File "/home/luka/etc/saion/ht_si/env/lib/python2.7/site-packages/django/shortcuts/__init__.py", line 20, in render_to_response
    return HttpResponse(loader.render_to_string(*args, **kwargs), **httpresponse_kwargs)
  File "/home/luka/etc/saion/ht_si/env/lib/python2.7/site-packages/django/template/loader.py", line 181, in render_to_string
    t = get_template(template_name)
  File "/home/luka/etc/saion/ht_si/env/lib/python2.7/site-packages/django/template/loader.py", line 157, in get_template
    template, origin = find_template(template_name)
  File "/home/luka/etc/saion/ht_si/env/lib/python2.7/site-packages/django/template/loader.py", line 134, in find_template
    source, display_name = loader(name, dirs)
  File "/home/luka/etc/saion/ht_si/env/lib/python2.7/site-packages/django/template/loader.py", line 42, in __call__
    return self.load_template(template_name, template_dirs)
  File "/home/luka/etc/saion/ht_si/env/lib/python2.7/site-packages/django/template/loader.py", line 48, in load_template
    template = get_template_from_string(source, origin, template_name)
  File "/home/luka/etc/saion/ht_si/env/lib/python2.7/site-packages/django/template/loader.py", line 168, in get_template_from_string
    return Template(source, origin, name)
  File "/home/luka/etc/saion/ht_si/env/lib/python2.7/site-packages/django/template/base.py", line 108, in __init__
    self.nodelist = compile_string(template_string, origin)
  File "/home/luka/etc/saion/ht_si/env/lib/python2.7/site-packages/django/template/base.py", line 136, in compile_string
    return parser.parse()
  File "/home/luka/etc/saion/ht_si/env/lib/python2.7/site-packages/django/template/base.py", line 239, in parse
    compiled_result = compile_func(self, token)
  File "/home/luka/etc/saion/ht_si/env/lib/python2.7/site-packages/django/template/loader_tags.py", line 214, in do_extends
    nodelist = parser.parse()
  File "/home/luka/etc/saion/ht_si/env/lib/python2.7/site-packages/django/template/base.py", line 239, in parse
    compiled_result = compile_func(self, token)
  File "/home/luka/etc/saion/ht_si/env/lib/python2.7/site-packages/django/template/loader_tags.py", line 192, in do_block
    nodelist = parser.parse(('endblock', 'endblock %s' % block_name))
  File "/home/luka/etc/saion/ht_si/env/lib/python2.7/site-packages/django/template/base.py", line 239, in parse
    compiled_result = compile_func(self, token)
  File "/home/luka/etc/saion/ht_si/env/lib/python2.7/site-packages/django/template/defaulttags.py", line 787, in do_for
    nodelist_loop = parser.parse(('empty', 'endfor',))
  File "/home/luka/etc/saion/ht_si/env/lib/python2.7/site-packages/django/template/base.py", line 239, in parse
    compiled_result = compile_func(self, token)
  File "/home/luka/etc/saion/ht_si/env/lib/python2.7/site-packages/django/template/defaulttags.py", line 787, in do_for
    nodelist_loop = parser.parse(('empty', 'endfor',))
  File "/home/luka/etc/saion/ht_si/env/lib/python2.7/site-packages/django/template/base.py", line 237, in parse
    self.invalid_block_tag(token, command, parse_until)
  File "/home/luka/etc/saion/ht_si/env/lib/python2.7/site-packages/django/template/base.py", line 290, in invalid_block_tag
    raise self.error(token, "Invalid block tag: '%s', expected %s" % (command, get_text_list(["'%s'" % p for p in parse_until])))
TemplateSyntaxError: Invalid block tag: 'vacancy_per_court', expected 'empty' or 'endfor'
2011-10-25 14:27:10,115 [WARNING] django.request: Not Found: /reservations/user_view
2011-10-25 15:23:28,684 [WARNING] django.request: Not Found: /accounts/edit_player_profile
2011-10-25 15:23:29,586 [WARNING] django.request: Not Found: /accounts/accounts.views.edit_player_profile
2011-10-25 15:24:47,743 [WARNING] django.request: Not Found: /accounts/edit_player_profile
2011-10-25 15:24:48,472 [WARNING] django.request: Not Found: /accounts/accounts.views.edit_player_profile
2011-10-26 08:55:36,043 [WARNING] django.request: Not Found: /accounts/edit_player_profile
2011-10-26 08:55:36,442 [WARNING] django.request: Not Found: /accounts/accounts.views.edit_player_profile
2011-10-26 09:10:11,125 [ERROR] django.request: Internal Server Error: /reservations/search
Traceback (most recent call last):
  File "/home/luka/etc/saion/ht_si/env/lib/python2.7/site-packages/django/core/handlers/base.py", line 111, in get_response
    response = callback(request, *callback_args, **callback_kwargs)
  File "/home/luka/etc/saion/ht_si/env/ht/reservations/views.py", line 251, in search
    context_instance=RequestContext(request))
  File "/home/luka/etc/saion/ht_si/env/lib/python2.7/site-packages/django/shortcuts/__init__.py", line 20, in render_to_response
    return HttpResponse(loader.render_to_string(*args, **kwargs), **httpresponse_kwargs)
  File "/home/luka/etc/saion/ht_si/env/lib/python2.7/site-packages/django/template/loader.py", line 188, in render_to_string
    return t.render(context_instance)
  File "/home/luka/etc/saion/ht_si/env/lib/python2.7/site-packages/django/template/base.py", line 123, in render
    return self._render(context)
  File "/home/luka/etc/saion/ht_si/env/lib/python2.7/site-packages/django/test/utils.py", line 60, in instrumented_test_render
    return self.nodelist.render(context)
  File "/home/luka/etc/saion/ht_si/env/lib/python2.7/site-packages/django/template/base.py", line 744, in render
    bits.append(self.render_node(node, context))
  File "/home/luka/etc/saion/ht_si/env/lib/python2.7/site-packages/django/template/debug.py", line 73, in render_node
    result = node.render(context)
  File "/home/luka/etc/saion/ht_si/env/lib/python2.7/site-packages/django/template/loader_tags.py", line 127, in render
    return compiled_parent._render(context)
  File "/home/luka/etc/saion/ht_si/env/lib/python2.7/site-packages/django/test/utils.py", line 60, in instrumented_test_render
    return self.nodelist.render(context)
  File "/home/luka/etc/saion/ht_si/env/lib/python2.7/site-packages/django/template/base.py", line 744, in render
    bits.append(self.render_node(node, context))
  File "/home/luka/etc/saion/ht_si/env/lib/python2.7/site-packages/django/template/debug.py", line 73, in render_node
    result = node.render(context)
  File "/home/luka/etc/saion/ht_si/env/lib/python2.7/site-packages/django/template/loader_tags.py", line 127, in render
    return compiled_parent._render(context)
  File "/home/luka/etc/saion/ht_si/env/lib/python2.7/site-packages/django/test/utils.py", line 60, in instrumented_test_render
    return self.nodelist.render(context)
  File "/home/luka/etc/saion/ht_si/env/lib/python2.7/site-packages/django/template/base.py", line 744, in render
    bits.append(self.render_node(node, context))
  File "/home/luka/etc/saion/ht_si/env/lib/python2.7/site-packages/django/template/debug.py", line 73, in render_node
    result = node.render(context)
  File "/home/luka/etc/saion/ht_si/env/lib/python2.7/site-packages/django/template/loader_tags.py", line 64, in render
    result = block.nodelist.render(context)
  File "/home/luka/etc/saion/ht_si/env/lib/python2.7/site-packages/django/template/base.py", line 744, in render
    bits.append(self.render_node(node, context))
  File "/home/luka/etc/saion/ht_si/env/lib/python2.7/site-packages/django/template/debug.py", line 73, in render_node
    result = node.render(context)
  File "/home/luka/etc/saion/ht_si/env/lib/python2.7/site-packages/django/template/loader_tags.py", line 64, in render
    result = block.nodelist.render(context)
  File "/home/luka/etc/saion/ht_si/env/lib/python2.7/site-packages/django/template/base.py", line 744, in render
    bits.append(self.render_node(node, context))
  File "/home/luka/etc/saion/ht_si/env/lib/python2.7/site-packages/django/template/debug.py", line 73, in render_node
    result = node.render(context)
  File "/home/luka/etc/saion/ht_si/env/lib/python2.7/site-packages/django/template/defaulttags.py", line 227, in render
    nodelist.append(node.render(context))
  File "/home/luka/etc/saion/ht_si/env/lib/python2.7/site-packages/django/template/defaulttags.py", line 227, in render
    nodelist.append(node.render(context))
  File "/home/luka/etc/saion/ht_si/env/lib/python2.7/site-packages/django/template/base.py", line 921, in render
    dict = func(*args)
  File "/home/luka/etc/saion/ht_si/env/ht/clubs/templatetags/vacancy_tags.py", line 25, in vacancy_per_hour
    h['vacancy'] = Vacancy.objects.get_all ([court], [dow], [h['value']])
  File "/home/luka/etc/saion/ht_si/env/ht/clubs/models.py", line 244, in get_all
    v = v.filter (court__in=court_list)
  File "/home/luka/etc/saion/ht_si/env/lib/python2.7/site-packages/django/db/models/query.py", line 550, in filter
    return self._filter_or_exclude(False, *args, **kwargs)
  File "/home/luka/etc/saion/ht_si/env/lib/python2.7/site-packages/django/db/models/query.py", line 568, in _filter_or_exclude
    clone.query.add_q(Q(*args, **kwargs))
  File "/home/luka/etc/saion/ht_si/env/lib/python2.7/site-packages/django/db/models/sql/query.py", line 1194, in add_q
    can_reuse=used_aliases, force_having=force_having)
  File "/home/luka/etc/saion/ht_si/env/lib/python2.7/site-packages/django/db/models/sql/query.py", line 1129, in add_filter
    connector)
  File "/home/luka/etc/saion/ht_si/env/lib/python2.7/site-packages/django/db/models/sql/where.py", line 67, in add
    value = obj.prepare(lookup_type, value)
  File "/home/luka/etc/saion/ht_si/env/lib/python2.7/site-packages/django/db/models/sql/where.py", line 316, in prepare
    return self.field.get_prep_lookup(lookup_type, value)
  File "/home/luka/etc/saion/ht_si/env/lib/python2.7/site-packages/django/db/models/fields/related.py", line 138, in get_prep_lookup
    return [self._pk_trace(v, 'get_prep_lookup', lookup_type) for v in value]
  File "/home/luka/etc/saion/ht_si/env/lib/python2.7/site-packages/django/db/models/fields/related.py", line 209, in _pk_trace
    v = getattr(field, prep_func)(lookup_type, v, **kwargs)
  File "/home/luka/etc/saion/ht_si/env/lib/python2.7/site-packages/django/db/models/fields/__init__.py", line 294, in get_prep_lookup
    return [self.get_prep_value(v) for v in value]
  File "/home/luka/etc/saion/ht_si/env/lib/python2.7/site-packages/django/db/models/fields/__init__.py", line 479, in get_prep_value
    return int(value)
TemplateSyntaxError: Caught TypeError while rendering: int() argument must be a string or a number, not 'dict'
2011-10-26 09:19:35,873 [ERROR] django.request: Internal Server Error: /reservations/search
Traceback (most recent call last):
  File "/home/luka/etc/saion/ht_si/env/lib/python2.7/site-packages/django/core/handlers/base.py", line 111, in get_response
    response = callback(request, *callback_args, **callback_kwargs)
  File "/home/luka/etc/saion/ht_si/env/ht/reservations/views.py", line 251, in search
    context_instance=RequestContext(request))
  File "/home/luka/etc/saion/ht_si/env/lib/python2.7/site-packages/django/shortcuts/__init__.py", line 20, in render_to_response
    return HttpResponse(loader.render_to_string(*args, **kwargs), **httpresponse_kwargs)
  File "/home/luka/etc/saion/ht_si/env/lib/python2.7/site-packages/django/template/loader.py", line 188, in render_to_string
    return t.render(context_instance)
  File "/home/luka/etc/saion/ht_si/env/lib/python2.7/site-packages/django/template/base.py", line 123, in render
    return self._render(context)
  File "/home/luka/etc/saion/ht_si/env/lib/python2.7/site-packages/django/test/utils.py", line 60, in instrumented_test_render
    return self.nodelist.render(context)
  File "/home/luka/etc/saion/ht_si/env/lib/python2.7/site-packages/django/template/base.py", line 744, in render
    bits.append(self.render_node(node, context))
  File "/home/luka/etc/saion/ht_si/env/lib/python2.7/site-packages/django/template/debug.py", line 73, in render_node
    result = node.render(context)
  File "/home/luka/etc/saion/ht_si/env/lib/python2.7/site-packages/django/template/loader_tags.py", line 127, in render
    return compiled_parent._render(context)
  File "/home/luka/etc/saion/ht_si/env/lib/python2.7/site-packages/django/test/utils.py", line 60, in instrumented_test_render
    return self.nodelist.render(context)
  File "/home/luka/etc/saion/ht_si/env/lib/python2.7/site-packages/django/template/base.py", line 744, in render
    bits.append(self.render_node(node, context))
  File "/home/luka/etc/saion/ht_si/env/lib/python2.7/site-packages/django/template/debug.py", line 73, in render_node
    result = node.render(context)
  File "/home/luka/etc/saion/ht_si/env/lib/python2.7/site-packages/django/template/loader_tags.py", line 127, in render
    return compiled_parent._render(context)
  File "/home/luka/etc/saion/ht_si/env/lib/python2.7/site-packages/django/test/utils.py", line 60, in instrumented_test_render
    return self.nodelist.render(context)
  File "/home/luka/etc/saion/ht_si/env/lib/python2.7/site-packages/django/template/base.py", line 744, in render
    bits.append(self.render_node(node, context))
  File "/home/luka/etc/saion/ht_si/env/lib/python2.7/site-packages/django/template/debug.py", line 73, in render_node
    result = node.render(context)
  File "/home/luka/etc/saion/ht_si/env/lib/python2.7/site-packages/django/template/loader_tags.py", line 64, in render
    result = block.nodelist.render(context)
  File "/home/luka/etc/saion/ht_si/env/lib/python2.7/site-packages/django/template/base.py", line 744, in render
    bits.append(self.render_node(node, context))
  File "/home/luka/etc/saion/ht_si/env/lib/python2.7/site-packages/django/template/debug.py", line 73, in render_node
    result = node.render(context)
  File "/home/luka/etc/saion/ht_si/env/lib/python2.7/site-packages/django/template/loader_tags.py", line 64, in render
    result = block.nodelist.render(context)
  File "/home/luka/etc/saion/ht_si/env/lib/python2.7/site-packages/django/template/base.py", line 744, in render
    bits.append(self.render_node(node, context))
  File "/home/luka/etc/saion/ht_si/env/lib/python2.7/site-packages/django/template/debug.py", line 73, in render_node
    result = node.render(context)
  File "/home/luka/etc/saion/ht_si/env/lib/python2.7/site-packages/django/template/defaulttags.py", line 227, in render
    nodelist.append(node.render(context))
  File "/home/luka/etc/saion/ht_si/env/lib/python2.7/site-packages/django/template/defaulttags.py", line 227, in render
    nodelist.append(node.render(context))
  File "/home/luka/etc/saion/ht_si/env/lib/python2.7/site-packages/django/template/base.py", line 921, in render
    dict = func(*args)
  File "/home/luka/etc/saion/ht_si/env/ht/clubs/templatetags/vacancy_tags.py", line 26, in vacancy_per_hour
    h['vacancy'] = Vacancy.objects.get_all ([court], [dow], [h['value']])
  File "/home/luka/etc/saion/ht_si/env/ht/clubs/models.py", line 244, in get_all
    v = v.filter (court__in=court_list)
  File "/home/luka/etc/saion/ht_si/env/lib/python2.7/site-packages/django/db/models/query.py", line 550, in filter
    return self._filter_or_exclude(False, *args, **kwargs)
  File "/home/luka/etc/saion/ht_si/env/lib/python2.7/site-packages/django/db/models/query.py", line 568, in _filter_or_exclude
    clone.query.add_q(Q(*args, **kwargs))
  File "/home/luka/etc/saion/ht_si/env/lib/python2.7/site-packages/django/db/models/sql/query.py", line 1194, in add_q
    can_reuse=used_aliases, force_having=force_having)
  File "/home/luka/etc/saion/ht_si/env/lib/python2.7/site-packages/django/db/models/sql/query.py", line 1129, in add_filter
    connector)
  File "/home/luka/etc/saion/ht_si/env/lib/python2.7/site-packages/django/db/models/sql/where.py", line 67, in add
    value = obj.prepare(lookup_type, value)
  File "/home/luka/etc/saion/ht_si/env/lib/python2.7/site-packages/django/db/models/sql/where.py", line 316, in prepare
    return self.field.get_prep_lookup(lookup_type, value)
  File "/home/luka/etc/saion/ht_si/env/lib/python2.7/site-packages/django/db/models/fields/related.py", line 138, in get_prep_lookup
    return [self._pk_trace(v, 'get_prep_lookup', lookup_type) for v in value]
  File "/home/luka/etc/saion/ht_si/env/lib/python2.7/site-packages/django/db/models/fields/related.py", line 209, in _pk_trace
    v = getattr(field, prep_func)(lookup_type, v, **kwargs)
  File "/home/luka/etc/saion/ht_si/env/lib/python2.7/site-packages/django/db/models/fields/__init__.py", line 294, in get_prep_lookup
    return [self.get_prep_value(v) for v in value]
  File "/home/luka/etc/saion/ht_si/env/lib/python2.7/site-packages/django/db/models/fields/__init__.py", line 479, in get_prep_value
    return int(value)
TemplateSyntaxError: Caught TypeError while rendering: int() argument must be a string or a number, not 'dict'
2011-10-26 10:44:14,743 [WARNING] django.request: Not Found: /reservations/player_edit/639/734436/ht_utils.views.success
2011-10-26 10:45:58,647 [WARNING] django.request: Not Found: /reservations/player_edit/639/734436/ht_utils.views.success
2011-10-30 19:38:36,370 [WARNING] django.request: Not Found: /favicon.ico
2011-10-30 19:38:38,634 [WARNING] django.request: Not Found: /favicon.ico
2011-10-30 19:38:45,221 [WARNING] django.request: Not Found: /favicon.ico
2011-10-30 19:38:49,221 [WARNING] django.request: Not Found: /favicon.ico
2011-10-30 19:38:56,424 [WARNING] django.request: Not Found: /favicon.ico
2011-10-30 19:39:02,968 [WARNING] django.request: Not Found: /favicon.ico
2011-10-30 19:39:06,892 [WARNING] django.request: Not Found: /favicon.ico
2011-10-30 19:45:00,080 [WARNING] django.request: Not Found: /favicon.ico
2011-10-30 19:45:07,464 [WARNING] django.request: Not Found: /favicon.ico
2011-10-30 19:45:09,937 [WARNING] django.request: Not Found: /favicon.ico
2011-10-30 19:45:14,697 [WARNING] django.request: Not Found: /favicon.ico
2011-10-30 19:46:01,769 [WARNING] django.request: Not Found: /favicon.ico
2011-10-30 19:54:38,559 [WARNING] django.request: Not Found: /favicon.ico
2011-10-30 19:56:02,077 [WARNING] django.request: Not Found: /favicon.ico
2011-10-30 20:04:16,107 [WARNING] django.request: Not Found: /favicon.ico
2011-10-30 20:04:29,622 [WARNING] django.request: Not Found: /favicon.ico
2011-10-30 20:04:43,357 [WARNING] django.request: Not Found: /favicon.ico
2011-10-30 20:04:45,338 [WARNING] django.request: Not Found: /favicon.ico
2011-10-30 20:05:00,437 [WARNING] django.request: Not Found: /favicon.ico
2011-10-30 20:05:05,108 [WARNING] django.request: Not Found: /favicon.ico
2011-10-30 20:05:44,120 [WARNING] django.request: Not Found: /favicon.ico
2011-10-30 20:29:57,766 [WARNING] django.request: Not Found: /favicon.ico
2011-10-30 20:31:36,503 [WARNING] django.request: Not Found: /favicon.ico
2011-10-30 20:31:41,331 [WARNING] django.request: Not Found: /favicon.ico
2011-10-30 20:33:04,118 [WARNING] django.request: Not Found: /favicon.ico
2011-10-30 20:33:26,458 [WARNING] django.request: Not Found: /favicon.ico
2011-10-30 20:33:29,031 [WARNING] django.request: Not Found: /favicon.ico
2011-10-30 20:33:39,291 [WARNING] django.request: Not Found: /favicon.ico
2011-10-30 20:33:43,190 [WARNING] django.request: Not Found: /favicon.ico
2011-10-30 20:39:26,140 [WARNING] django.request: Not Found: /favicon.ico
2011-10-30 20:39:28,634 [WARNING] django.request: Not Found: /favicon.ico
2011-10-30 20:42:25,109 [WARNING] django.request: Not Found: /favicon.ico
2011-10-30 20:42:28,657 [WARNING] django.request: Not Found: /favicon.ico
2011-10-30 20:42:31,366 [WARNING] django.request: Not Found: /favicon.ico
2011-10-30 20:47:11,363 [WARNING] django.request: Not Found: /favicon.ico
2011-10-30 20:47:14,494 [WARNING] django.request: Not Found: /favicon.ico
2011-10-30 20:56:22,868 [WARNING] django.request: Not Found: /accounts/edit_player_profile
2011-10-30 20:56:25,261 [WARNING] django.request: Not Found: /accounts/accounts.views.edit_player_profile
2011-10-31 16:04:30,635 [WARNING] django.request: Not Found: /accounts/edit_player_profile
2011-10-31 16:04:32,594 [WARNING] django.request: Not Found: /accounts/accounts.views.edit_player_profile
2011-10-31 16:12:36,015 [WARNING] django.request: Not Found: /accounts/edit_player_profile
2011-10-31 16:12:37,903 [WARNING] django.request: Not Found: /accounts/accounts.views.edit_player_profile
2011-10-31 17:11:11,568 [WARNING] django.request: Not Found: /media/admin/css/base.css
2011-10-31 17:11:11,617 [WARNING] django.request: Not Found: /media/admin/css/login.css
2011-10-31 17:17:21,994 [WARNING] django.request: Not Found: /media
2011-10-31 17:17:37,536 [WARNING] django.request: Not Found: /media/admin/css/base.css
2011-10-31 17:17:54,533 [WARNING] django.request: Not Found: /static
2011-10-31 17:35:10,606 [WARNING] django.request: Not Found: /media/upload/comment_photos/test.jpg
2011-10-31 18:29:36,423 [WARNING] django.request: Not Found: /accounts/edit_player_profile
2011-10-31 18:29:38,227 [WARNING] django.request: Not Found: /accounts/accounts.views.edit_player_profile
2011-10-31 19:31:49,736 [WARNING] django.request: Not Found: /accounts/edit_player_profile
2011-10-31 19:31:51,442 [WARNING] django.request: Not Found: /accounts/accounts.views.edit_player_profile
2011-10-31 19:33:47,180 [WARNING] django.request: Not Found: /accounts/edit_player_profile
2011-10-31 19:33:48,944 [WARNING] django.request: Not Found: /accounts/accounts.views.edit_player_profile
2011-10-31 19:35:34,661 [WARNING] django.request: Not Found: /accounts/edit_player_profile
2011-10-31 19:35:36,539 [WARNING] django.request: Not Found: /accounts/accounts.views.edit_player_profile
2011-10-31 19:38:53,249 [WARNING] django.request: Not Found: /accounts/edit_player_profile
2011-10-31 19:38:55,027 [WARNING] django.request: Not Found: /accounts/accounts.views.edit_player_profile
2011-10-31 19:53:08,284 [WARNING] django.request: Not Found: /accounts/edit_player_profile
2011-10-31 19:53:10,145 [WARNING] django.request: Not Found: /accounts/accounts.views.edit_player_profile
2011-11-01 09:00:57,815 [WARNING] django.request: Not Found: /accounts/edit_player_profile
2011-11-01 09:07:29,553 [WARNING] django.request: Not Found: /accounts/edit_player_profile
2011-11-01 09:26:25,568 [WARNING] django.request: Not Found: /accounts/edit_player_profile
2011-11-01 09:26:27,246 [WARNING] django.request: Not Found: /accounts/accounts.views.edit_player_profile
2011-11-01 09:31:01,032 [WARNING] django.request: Not Found: /accounts/edit_player_profile
2011-11-01 09:31:02,711 [WARNING] django.request: Not Found: /accounts/accounts.views.edit_player_profile
2011-11-01 09:32:31,967 [WARNING] django.request: Not Found: /accounts/edit_player_profile
2011-11-01 09:32:33,636 [WARNING] django.request: Not Found: /accounts/accounts.views.edit_player_profile
2011-11-01 10:25:41,008 [WARNING] django.request: Not Found: /accounts/edit_player_profile
2011-11-01 10:25:42,627 [WARNING] django.request: Not Found: /accounts/accounts.views.edit_player_profile
2011-11-01 10:32:38,453 [WARNING] django.request: Not Found: /accounts/edit_player_profile
2011-11-01 10:32:40,333 [WARNING] django.request: Not Found: /accounts/accounts.views.edit_player_profile
2011-11-01 11:08:29,860 [WARNING] django.request: Not Found: /accounts/edit_player_profile
2011-11-01 11:08:30,388 [ERROR] django.request: Internal Server Error: /
Traceback (most recent call last):
  File "/home/luka/etc/saion/ht_si/env/lib/python2.6/site-packages/django/core/handlers/base.py", line 111, in get_response
    response = callback(request, *callback_args, **callback_kwargs)
  File "/home/luka/etc/saion/ht_si/env/ht/../ht/views.py", line 11, in home
    context_instance=RequestContext(request))
  File "/home/luka/etc/saion/ht_si/env/lib/python2.6/site-packages/django/shortcuts/__init__.py", line 20, in render_to_response
    return HttpResponse(loader.render_to_string(*args, **kwargs), **httpresponse_kwargs)
  File "/home/luka/etc/saion/ht_si/env/lib/python2.6/site-packages/django/template/loader.py", line 181, in render_to_string
    t = get_template(template_name)
  File "/home/luka/etc/saion/ht_si/env/lib/python2.6/site-packages/django/template/loader.py", line 157, in get_template
    template, origin = find_template(template_name)
  File "/home/luka/etc/saion/ht_si/env/lib/python2.6/site-packages/django/template/loader.py", line 138, in find_template
    raise TemplateDoesNotExist(name)
TemplateDoesNotExist: home.html
2011-11-01 11:13:04,348 [WARNING] django.request: Not Found: /accounts/edit_player_profile
2011-11-01 11:13:06,213 [WARNING] django.request: Not Found: /accounts/accounts.views.edit_player_profile
2011-11-01 11:16:02,217 [WARNING] django.request: Not Found: /accounts/edit_player_profile
2011-11-01 11:16:04,062 [WARNING] django.request: Not Found: /accounts/accounts.views.edit_player_profile
2011-11-01 11:17:35,946 [WARNING] django.request: Not Found: /accounts/edit_player_profile
2011-11-01 11:17:37,769 [WARNING] django.request: Not Found: /accounts/accounts.views.edit_player_profile
2011-11-01 12:11:28,393 [WARNING] django.request: Not Found: /accounts/edit_player_profile
2011-11-01 12:11:30,202 [WARNING] django.request: Not Found: /accounts/accounts.views.edit_player_profile
2011-11-01 13:44:38,927 [WARNING] django.request: Not Found: /accounts/edit_player_profile
2011-11-01 13:44:40,671 [WARNING] django.request: Not Found: /accounts/accounts.views.edit_player_profile
2011-11-01 13:53:54,254 [WARNING] django.request: Not Found: /accounts/edit_player_profile
2011-11-01 13:53:56,000 [WARNING] django.request: Not Found: /accounts/accounts.views.edit_player_profile
2011-11-01 16:26:02,170 [ERROR] django.request: Internal Server Error: /clubs/save_court_vacancy/27/
Traceback (most recent call last):
  File "/home/luka/etc/saion/ht_si/env/lib/python2.6/site-packages/django/core/handlers/base.py", line 111, in get_response
    response = callback(request, *callback_args, **callback_kwargs)
  File "/home/luka/etc/saion/ht_si/env/lib/python2.6/site-packages/django/contrib/auth/decorators.py", line 23, in _wrapped_view
    return view_func(request, *args, **kwargs)
  File "/home/luka/etc/saion/ht_si/env/ht/clubs/views.py", line 150, in save_court_vacancy
    Vacancy.objects.filter (id__in=prices[p]).update (price=p)
  File "/home/luka/etc/saion/ht_si/env/lib/python2.6/site-packages/django/db/models/query.py", line 467, in update
    rows = query.get_compiler(self.db).execute_sql(None)
  File "/home/luka/etc/saion/ht_si/env/lib/python2.6/site-packages/django/db/models/sql/compiler.py", line 869, in execute_sql
    cursor = super(SQLUpdateCompiler, self).execute_sql(result_type)
  File "/home/luka/etc/saion/ht_si/env/lib/python2.6/site-packages/django/db/models/sql/compiler.py", line 725, in execute_sql
    sql, params = self.as_sql()
  File "/home/luka/etc/saion/ht_si/env/lib/python2.6/site-packages/django/db/models/sql/compiler.py", line 834, in as_sql
    val = field.get_db_prep_save(val, connection=self.connection)
  File "/home/luka/etc/saion/ht_si/env/lib/python2.6/site-packages/django/db/models/fields/subclassing.py", line 28, in inner
    return func(*args, **kwargs)
  File "/home/luka/etc/saion/ht_si/env/lib/python2.6/site-packages/django/db/models/fields/__init__.py", line 786, in get_db_prep_save
    return connection.ops.value_to_db_decimal(self.to_python(value),
  File "/home/luka/etc/saion/ht_si/env/lib/python2.6/site-packages/django/db/models/fields/__init__.py", line 761, in to_python
    return decimal.Decimal(value)
  File "/usr/lib/python2.6/decimal.py", line 649, in __new__
    "First convert the float to a string")
TypeError: Cannot convert float to Decimal.  First convert the float to a string
2011-11-01 17:22:58,620 [WARNING] django.request: Not Found: /accounts/edit_player_profile
2011-11-01 17:23:00,367 [WARNING] django.request: Not Found: /accounts/accounts.views.edit_player_profile
2011-11-01 18:16:10,666 [WARNING] django.request: Not Found: /accounts/img/personal_information.png
2011-11-01 18:16:10,852 [WARNING] django.request: Not Found: /accounts/img/personal_information.png
2011-11-01 18:16:20,540 [WARNING] django.request: Not Found: /accounts/img/personal_information.png
2011-11-01 18:16:20,660 [WARNING] django.request: Not Found: /accounts/img/personal_information.png
2011-11-01 18:18:00,207 [WARNING] django.request: Not Found: /accounts/img/personal_information.png
2011-11-01 18:18:00,407 [WARNING] django.request: Not Found: /accounts/img/personal_information.png
2011-11-01 18:18:18,671 [WARNING] django.request: Not Found: /accounts/img/personal_information.png
2011-11-01 18:18:18,816 [WARNING] django.request: Not Found: /accounts/img/personal_information.png
2011-11-01 18:21:10,069 [WARNING] django.request: Not Found: /accounts/img/matches.png
2011-11-01 18:21:10,247 [WARNING] django.request: Not Found: /accounts/img/matches.png
2011-11-02 16:05:48,543 [WARNING] django.request: Not Found: /accounts/edit_player_profile
2011-11-02 16:05:48,848 [WARNING] django.request: Not Found: /accounts/accounts.views.edit_player_profile
2011-11-02 19:11:42,209 [WARNING] django.request: Not Found: /favicon.ico
2011-11-02 19:11:45,437 [WARNING] django.request: Not Found: /favicon.ico
2011-11-02 19:11:50,902 [WARNING] django.request: Not Found: /favicon.ico
2011-11-02 19:11:53,518 [WARNING] django.request: Not Found: /favicon.ico
2011-11-02 19:12:01,844 [WARNING] django.request: Not Found: /favicon.ico
2011-11-02 20:14:23,115 [WARNING] django.request: Not Found: /clubs/toggle_active_court_setup/7/accounts.views.display_club_profile
2011-11-02 20:16:34,397 [WARNING] django.request: Not Found: /clubs/toggle_active_court_setup/7/accounts.views.display_club_profile
2011-11-02 20:18:33,886 [WARNING] django.request: Not Found: /clubs/toggle_active_court_setup/7/accounts.views.display_club_profile
2011-11-02 20:21:05,179 [WARNING] django.request: Not Found: /clubs/toggle_active_court_setup/7/accounts.views.display_club_profile
2011-11-02 21:23:18,782 [WARNING] django.request: Not Found: /accounts/edit_player_profile
2011-11-02 21:23:19,013 [WARNING] django.request: Not Found: /accounts/accounts.views.edit_player_profile
2011-11-02 21:23:42,724 [WARNING] django.request: Not Found: /accounts/edit_player_profile
2011-11-02 21:23:42,957 [WARNING] django.request: Not Found: /accounts/accounts.views.edit_player_profile
2011-11-03 09:50:06,041 [WARNING] django.request: Not Found: /accounts/edit_player_profile
2011-11-03 09:50:06,673 [WARNING] django.request: Not Found: /accounts/accounts.views.edit_player_profile
2011-11-03 11:09:31,390 [WARNING] django.request: Not Found: /accounts/edit_player_profile
2011-11-03 11:09:31,938 [WARNING] django.request: Not Found: /accounts/accounts.views.edit_player_profile
2011-11-03 16:54:38,267 [WARNING] django.request: Not Found: /accounts/edit_player_profile
2011-11-03 16:54:38,943 [WARNING] django.request: Not Found: /accounts/accounts.views.edit_player_profile
2011-11-03 19:17:23,665 [WARNING] django.request: Not Found: /accounts/edit_player_profile
2011-11-03 19:17:24,257 [WARNING] django.request: Not Found: /accounts/accounts.views.edit_player_profile
2011-11-03 22:19:32,111 [WARNING] django.request: Not Found: /accounts/edit_player_profile
2011-11-03 22:19:32,365 [WARNING] django.request: Not Found: /accounts/accounts.views.edit_player_profile
2011-11-03 22:28:49,600 [WARNING] django.request: Not Found: /accounts/edit_player_profile
2011-11-03 22:28:49,836 [WARNING] django.request: Not Found: /accounts/accounts.views.edit_player_profile
